Workbook

Sheet Supplementary Table 2
K1: Eckhard et al. 2015
A4: Supplementary Table 2: Human MMP cleavage sites identified by PICS in GluC-generated human proteome libraries
A6: Human MMP | B6: MMP1 | C6: MMP2 | D6: MMP3 | E6: MMP7 | F6: MMP8 | G6: MMP9 | H6: MMP12 | I6: MMP13 | J6: MMP14 | K6: Total
A7: Number of cleavage sites | B7: 134 | C7: 270 | D7: 168 | E7: 176 | F7: 128 | G7: 168 | H7: 136 | I7: 135 | J7: 235 | K7: =SUM(B7:J7) -> 1550
A8: Unique P6-to-P6' cleavage sites | B8: 126 | C8: 246 | D8: 151 | E8: 163 | F8: 120 | G8: 146 | H8: 124 | I8: 130 | J8: 213 | K8: =SUM(B8:J8) -> 1419

Sheet MMP1-G
A1: Supplementary Table 2a: Human MMP1 cleavage sites identified by PICS in GluC-generated human proteome libraries | J1: back to index
A2: Peptides were identified by LC-MS/MS spectrum-to-sequence assignment with Mascot and X! Tandem, and further analysed by iProphet within TPP at a false-discovery rate of 1%. iProphet probability score, spectrum ID, peptide sequence, and scores by Mascot (ionscore, identity score, homology score) and X! Tandem (hyperscore, nextscore, bscore, yscore) are shown together with other peptide and peptide-spectrum match measures. One exemplary accession number of a matching UniProt protein entry is listed. K[156.13] denotes lysine labeled by heavy-dimethyl, C[160.03] and M[147.04] represent carbamidomethylated cysteine and oxidized methionine, respectively, and n[89.01] indicates thioacylated N-termini. Data were further processed and rendered non-redundant for generation of cleavage specificity profiles via WebPICS (http://clipserve.clip.ubc.ca/pics/) and iceLogo (http://iomics.ugent.be/icelogoserver/).
A3: probability | B3: spectrum | C3: start scan | D3: ions | E3: peptide | F3: protein | G3: calculated neutral peptide mass | H3: index | I3: assumed charge | J3: precursor neutral mass | K3: m/z ratio | L3: protein description | M3: pI | N3: retention time (sec) | O3: ppm | P3: hyperscore | Q3: nextscore | R3: bscore | S3: yscore | T3: expect | U3: mass diff | V3: fval
A4: 0.9951 | B4: MegaP_hMMP1_GluC_GB_QStar-XL_20110627.01934.01934.3 | C4: 1934 | D4: 13/48 | E4: D.n[29.04]YTK[156.13]HPAK[156.13]PDPSGE.C | F4: sp|Q16576|RBBP7_HUMAN,sp|Q16576-2|RBBP7_HUMAN | G4: 1509.7827 | H4: 789 | I4: 3 | J4: 1509.7927 | K4: 504.2682 | L4: Histone-binding protein RBBP7 OS=Homo sapiens GN=RBBP7 PE=1 SV=1 | M4: 6.77 | N4: 2077.04 | O4: 6.610239 | P4: 30.3 | Q4: 23 | R4: 11.8 | S4: 10.6 | T4: 0.016 | U4: 0.01 | V4: 3.8302
A5: 0.9917 | B5: MegaP_hMMP1_GluC_GB_QStar-XL_20110627.01939.01939.3 | C5: 1939 | D5: 14/48 | E5: D.n[29.04]YTK[156.13]HPSK[156.13]PDPSGE.C | F5: sp|Q09028|RBBP4_HUMAN,sp|Q09028-2|RBBP4_HUMAN,sp|Q09028-3|RBBP4_HUMAN,sp|Q09028-4|RBBP4_HUMAN | G5: 1525.7777 | H5: 322 | I5: 3 | J5: 1525.7897 | K5: 509.5998 | L5: Histone-binding protein RBBP4 OS=Homo sapiens GN=RBBP4 PE=1 SV=3 | M5: 6.77 | N5: 2086.49 | O5: 7.8492966 | P5: 33.7 | Q5: 26.2 | R5: 11.8 | S5: 11.2 | T5: 0.022 | U5: 0.012 | V5: 3.5516
A6: 0.9998 | B6: MegaP_hMMP1_GluC_GB_QStar-XL_20110627.02126.02126.3 | C6: 2126 | D6: 14/36 | E6: D.n[89.01]MK[156.13]THK[156.13]NPALK[156.13].A | F6: sp|Q01518|CAP1_HUMAN,sp|Q01518-2|CAP1_HUMAN | G6: 1338.7516 | H6: 7 | I6: 3 | J6: 1338.744 | K6: 447.2578 | L6: Adenylyl cyclase-associated protein 1 OS=Homo sapiens GN=CAP1 PE=1 SV=5 | M6: 10.3 | N6: 2428.38 | O6: -5.6641457 | P6: 30 | Q6: 19.3 | R6: 10.7 | S6: 11.4 | T6: 0.00069 | U6: -0.0076 | V6: 7.0593
A7: 0.9895 | B7: MegaP_hMMP1_GluC_GB_QStar-XL_20110627.02132.02132.3 | C7: 2132 | D7: 11/36 | E7: M.n[29.04]APK[156.13]PGPYVK[156.13]E.M | F7: sp|Q01518|CAP1_HUMAN,sp|Q01518-2|CAP1_HUMAN | G7: 1168.6856 | H7: 557 | I7: 3 | J7: 1168.6925 | K7: 390.5691 | L7: Adenylyl cyclase-associated protein 1 OS=Homo sapiens GN=CAP1 PE=1 SV=5 | M7: 8.54 | N7: 2442.05 | O7: 5.8888427 | P7: 28.8 | Q7: 20.9 | R7: 8 | S7: 11.6 | T7: 0.026 | U7: 0.0069 | V7: 4.2431
A8: 0.9927 | B8: MegaP_hMMP1_GluC_GB_QStar-XL_20110627.02135.02135.2 | C8: 2135 | D8: 14/14 | E8: N.n[89.01]TAAQK[156.13]VSH.L | F8: sp|P35579|MYH9_HUMAN | G8: 956.4749 | H8: 991 | I8: 2 | J8: 956.4744 | K8: 479.2447 | L8: Myosin-9 OS=Homo sapiens GN=MYH9 PE=1 SV=4 | M8: 8.44 | N8: 2443.1 | O8: -0.52165418 | P8: 41.6 | Q8: 29.7 | R8: 10 | S8: 10.9 | T8: 0.011 | U8: -0.0005 | V8: 4.5693
A9: 0.9967 | B9: MegaP_hMMP1_GluC_GB_QStar-XL_20110627.02154.02154.3 | C9: 2154 | D9: 14/44 | E9: D.n[89.01]MK[156.13]THK[156.13]NPALK[156.13]AQ.S | F9: sp|Q01518|CAP1_HUMAN,sp|Q01518-2|CAP1_HUMAN | G9: 1537.8473 | H9: 377 | I9: 3 | J9: 1537.8447 | K9: 513.623 | L9: Adenylyl cyclase-associated protein 1 OS=Homo sapiens GN=CAP1 PE=1 SV=5 | M9: 10.3 | N9: 2479.83 | O9: -1.6873595 | P9: 31 | Q9: 21.7 | R9: 12.2 | S9: 12.1 | T9: 0.023 | U9: -0.0026 | V9: 4.11
A10: 0.989 | B10: MegaP_hMMP1_GluC_GB_QStar-XL_20110627.02219.02219.3 | C10: 2219 | D10: 15/56 | E10: E.n[29.04]HSVNYK[156.13]PPAQK[156.13]SIQE.L | F10: sp|P52565|GDIR1_HUMAN,sp|P52565-2|GDIR1_HUMAN | G10: 1808.9787 | H10: 781 | I10: 3 | J10: 1809.0013 | K10: 604.0002 | L10: Rho GDP-dissociation inhibitor 1 OS=Homo sapiens GN=ARHGDIA PE=1 SV=3 | M10: 8.51 | N10: 2601.32 | O10: 12.472402 | P10: 30.1 | Q10: 22.5 | R10: 7.9 | S10: 8.8 | T10: 0.033 | U10: 0.0226 | V10: 3.2654
A11: 0.9744 | B11: MegaP_hMMP1_GluC_GB_QStar-XL_20110627.02247.02247.3 | C11: 2247 | D11: 12/48 | E11: E.n[29.04]GVHGGLINK[156.13]K[156.13]C[160.03]YE.M | F11: sp|P07737|PROF1_HUMAN | G11: 1557.8337 | H11: 787 | I11: 3 | J11: 1557.8382 | K11: 520.2852 | L11: Profilin-1 OS=Homo sapiens GN=PFN1 PE=1 SV=2 | M11: 8.18 | N11: 2652.57 | O11: 2.8830342 | P11: 29 | Q11: 22.9 | R11: 8.8 | S11: 11.7 | T11: 0.086 | U11: 0.0045 | V11: 2.7277
A12: 0.9967 | B12: MegaP_hMMP1_GluC_GB_QStar-XL_20110627.02287.02287.2 | C12: 2287 | D12: 17/18 | E12: F.n[89.01]INTSK[156.13]GQK[156.13]C[160.03]E.F | F12: sp|P10809|CH60_HUMAN | G12: 1307.6217 | H12: 208 | I12: 2 | J12: 1307.6353 | K12: 654.8181 | L12: 60 kDa heat shock protein, mitochondrial OS=Homo sapiens GN=HSPD1 PE=1 SV=2 | M12: 8.2 | N12: 2725.92 | O12: 10.384563 | P12: 52.4 | Q12: 38.2 | R12: 9.2 | S12: 9.5 | T12: 0.00024 | U12: 0.0136 | V12: 5.9883
A13: 0.9997 | B13: MegaP_hMMP1_GluC_GB_QStar-XL_20110627.02288.02288.3 | C13: 2288 | D13: 19/48 | E13: E.n[29.04]RHYGGLTGLNK[156.13]AE.T | F13: sp|P18669|PGAM1_HUMAN,sp|P15259|PGAM2_HUMAN,sp|Q8N0Y7|PGAM4_HUMAN | G13: 1470.7947 | H13: 645 | I13: 3 | J13: 1470.8084 | K13: 491.2722 | L13: Phosphoglycerate mutase 1 OS=Homo sapiens GN=PGAM1 PE=1 SV=2 | M13: 8.6 | N13: 2728.02 | O13: 9.2955935 | P13: 44.6 | Q13: 28.7 | R13: 11.1 | S13: 11.1 | T13: 0.00021 | U13: 0.0137 | V13: 6.8749
A14: 0.9977 | B14: MegaP_hMMP1_GluC_GB_QStar-XL_20110627.02346.02346.3 | C14: 2346 | D14: 16/56 | E14: G.n[29.04]QSGAGNNWAK[156.13]GHYTE.G | F14: sp|P07437|TBB5_HUMAN,sp|Q13885|TBB2A_HUMAN,sp|Q9BVA1|TBB2B_HUMAN,sp|Q13509|TBB3_HUMAN,sp|P04350|TBB4A_HUMAN,sp|P68371|TBB4B_HUMAN | G14: 1674.7747 | H14: 676 | I14: 3 | J14: 1674.7863 | K14: 559.2655 | L14: Tubulin beta chain OS=Homo sapiens GN=TUBB PE=1 SV=2 | M14: 6.76 | N14: 2833.58 | O14: 6.9138301 | P14: 32.6 | Q14: 20.3 | R14: 7.4 | S14: 7.3 | T14: 0.0011 | U14: 0.0116 | V14: 5.6663
A15: 0.9961 | B15: MegaP_hMMP1_GluC_GB_QStar-XL_20110627.02380.02380.3 | C15: 2380 | D15: 14/48 | E15: H.n[29.04]K[156.13]NPALK[156.13]AQSGPVR.S | F15: sp|Q01518|CAP1_HUMAN | G15: 1448.8827 | H15: 935 | I15: 3 | J15: 1448.7781 | K15: 483.9682 | L15: Adenylyl cyclase-associated protein 1 OS=Homo sapiens GN=CAP1 PE=1 SV=5 | M15: 11.17 | N15: 2896.43 | O15: -72.043301 | P15: 34.8 | Q15: 22.9 | R15: 8.5 | S15: 13.2 | T15: 0.00058 | U15: -0.1046 | V15: 6.2307
... A192: 0.9684 | B192: MegaP_hMMP1_GluC_GB_QStar-XL_20110627.04995.04995.2 | C192: 4995 | D192: 10/18 | E192: K.n[89.01]LLQDFFNGK[156.13]E.L | F192: sp|P11142|HSP7C_HUMAN | G192: 1325.6325 | H192: 1155 | I192: 2 | J192: 1325.6402 | K192: 663.8235 | L192: Heat shock cognate 71 kDa protein OS=Homo sapiens GN=HSPA8 PE=1 SV=1 | M192: 4.75 | N192: 7672.05 | O192: 5.7997344 | P192: 33 | Q192: 26 | R192: 12 | S192: 12.3 | T192: 0.04 | U192: 0.0077 | V192: 3.1019

Sheet MMP2-G
A1: Supplementary Table S2b: Human MMP2 cleavage sites identified by PICS in GluC-generated human proteome libraries | J1: back to index
A2: Peptides were identified by LC-MS/MS spectrum-to-sequence assignment with Mascot and X! Tandem, and further analysed by iProphet within TPP at a false-discovery rate of 1%. iProphet probability score, spectrum ID, peptide sequence, and scores by Mascot (ionscore, identity score, homology score) and X! Tandem (hyperscore, nextscore, bscore, yscore) are shown together with other peptide and peptide-spectrum match measures. One exemplary accession number of a matching UniProt protein entry is listed. K[156.13] denotes lysine labeled by heavy-dimethyl, C[160.03] and M[147.04] represent carbamidomethylated cysteine and oxidized methionine, respectively, and n[89.01] indicates thioacylated N-termini. Data were further processed and rendered non-redundant for generation of cleavage specificity profiles via WebPICS (http://clipserve.clip.ubc.ca/pics/) and iceLogo (http://iomics.ugent.be/icelogoserver/).
A3: ='MMP1-G'!A3 -> probability | B3: ='MMP1-G'!B3 -> spectrum | C3: ='MMP1-G'!C3 -> start scan | D3: ='MMP1-G'!D3 -> ions | E3: ='MMP1-G'!E3 -> peptide | F3: ='MMP1-G'!F3 -> protein | G3: ='MMP1-G'!G3 -> calculated neutral peptide mass | H3: ='MMP1-G'!H3 -> index | ... V3: ='MMP1-G'!V3 -> fval
A4: 0.9908 | B4: MegaP_hMMP2_GluC-1_OS_QStar-XL_20111027.01759.01759.3 | C4: 1759 | D4: 11/56 | E4: E.n[29.04]VK[156.13]NK[156.13]IASK[156.13]YDHQAEE.D | F4: sp|Q15417|CNN3_HUMAN | G4: 1871.0157 | H4: 877 | I4: 3 | J4: 1871.0736 | K4: 624.6792 | L4: Calponin-3 OS=Homo sapiens GN=CNN3 PE=1 SV=1 | M4: 6.74 | N4: 1876.53 | O4: 30.895858 | P4: 28.2 | Q4: 22.3 | R4: 10.5 | S4: 10.1 | T4: 0.0099 | U4: 0.0579 | V4: 3.6637
A5: 0.9931 | B5: MegaP_hMMP2_GluC-1_OS_QStar-XL_20111027.01761.01761.3 | C5: 1761 | D5: 13/36 | E5: D.n[89.01]K[156.13]K[156.13]K[156.13]VLDK[156.13]C[160.03]QE.V | F5: sp|P08107|HSP71_HUMAN,sp|P08107-2|HSP71_HUMAN | G5: 1474.8247 | H5: 535 | I5: 3 | J5: 1474.8828 | K5: 492.6155 | L5: Heat shock 70 kDa protein 1A\1B OS=Homo sapiens GN=HSPA1A PE=1 SV=5 | M5: 9.11 | N5: 1877.57 | O5: 39.313961 | P5: 26.6 | Q5: 21 | R5: 9 | S5: 7.5 | T5: 0.038 | U5: 0.0581 | V5: 3.5997
A6: 0.95 | B6: MegaP_hMMP2_GluC-1_OS_QStar-XL_20111027.01762.01762.3 | C6: 1762 | D6: 9/56 | E6: E.n[29.04]DAC[160.03]YNC[160.03]GRGGHIAK[156.13]D.C | F6: sp|P62633|CNBP_HUMAN,sp|P62633-2|CNBP_HUMAN,sp|P62633-3|CNBP_HUMAN | G6: 1748.7727 | H6: 1 | I6: 3 | J6: 1748.8211 | K6: 583.9315 | L6: Cellular nucleic acid-binding protein OS=Homo sapiens GN=CNBP PE=1 SV=1 | M6: 6.74 | N6: 1877.57 | O6: 27.628811 | P6: 21.2 | Q6: 17.6 | R6: 6.2 | S6: 8.1 | T6: 0.13 | U6: 0.0484 | V6: 2.1305
A7: 0.9856 | B7: MegaP_hMMP2_GluC-1_OS_QStar-XL_20111027.01776.01776.3 | C7: 1776 | D7: 16/60 | E7: S.n[29.04]SSAASNNHQVGSGNDP.W | F7: sp|Q9Y5X1|SNX9_HUMAN | G7: 1568.6817 | H7: 1369 | I7: 3 | J7: 1568.7918 | K7: 523.9012 | L7: Sorting nexin-9 OS=Homo sapiens GN=SNX9 PE=1 SV=1 | M7: 5.06 | N7: 1906.72 | O7: 70.051376 | P7: 34.9 | Q7: 25.7 | R7: 10.8 | S7: 10.2 | T7: 0.0049 | U7: 0.1101 | V7: 4.1773
A8: 0.982 | B8: MegaP_hMMP2_GluC-1_OS_QStar-XL_20111027.01863.01863.3 | C8: 1863 | D8: 13/52 | E8: E.n[29.04]SK[156.13]ADDPYAHLSK[156.13]K[156.13]E.K | F8: sp|Q8NE71|ABCF1_HUMAN | G8: 1699.9147 | H8: 72 | I8: 3 | J8: 1699.9711 | K8: 567.6455 | L8: ATP-binding cassette sub-family F member 1 OS=Homo sapiens GN=ABCF1 PE=1 SV=2 | M8: 6.49 | N8: 2103.88 | O8: 33.119262 | P8: 30.3 | Q8: 22.7 | R8: 13.6 | S8: 13.1 | T8: 0.04 | U8: 0.0564 | V8: 3.2613
A9: 0.9996 | B9: MegaP_hMMP2_GluC-1_OS_QStar-XL_20111027.01878.01878.2 | C9: 1878 | D9: 11/20 | E9: E.n[29.04]YHSEPVEDEK[156.13]P.- | F9: sp|P26196|DDX6_HUMAN | G9: 1384.6507 | H9: 1306 | I9: 2 | J9: 1384.6621 | K9: 693.3326 | L9: Probable ATP-dependent RNA helicase DDX6 OS=Homo sapiens GN=DDX6 PE=1 SV=2 | M9: 4.4 | N9: 2146.62 | O9: 8.2211625 | P9: 29.7 | Q9: 19.5 | R9: 6.2 | S9: 7.6 | T9: 0.0069 | U9: 0.0114 | V9: 4.4574
A10: 0.9789 | B10: MegaP_hMMP2_GluC-1_OS_QStar-XL_20111027.01881.01881.3 | C10: 1881 | D10: 14/48 | E10: E.n[29.04]YDGHSTYPSHQYQ.- | F10: sp|P30043|BLVRB_HUMAN | G10: 1609.6797 | H10: 73 | I10: 3 | J10: 1609.7375 | K10: 537.5672 | L10: Flavin reductase (NADPH) OS=Homo sapiens GN=BLVRB PE=1 SV=3 | M10: 5.97 | N10: 2147.68 | O10: 35.84048 | P10: 28.2 | Q10: 22.2 | R10: 6.7 | S10: 8.6 | T10: 0.04 | U10: 0.0578 | V10: 3.1657
A11: 0.9896 | B11: MegaP_hMMP2_GluC-1_OS_QStar-XL_20111027.01898.01898.3 | C11: 1898 | D11: 13/44 | E11: E.n[89.01]VRHLK[156.13]TK[156.13]PSDEE.M | F11: sp|P07108|ACBP_HUMAN,sp|P07108-2|ACBP_HUMAN,sp|P07108-3|ACBP_HUMAN,sp|P07108-4|ACBP_HUMAN,sp|P07108-5|ACBP_HUMAN,sp|P07108-6|ACBP_HUMAN | G11: 1581.8187 | H11: 901 | I11: 3 | J11: 1581.8651 | K11: 528.2802 | L11: Acyl-CoA-binding protein OS=Homo sapiens GN=DBI PE=1 SV=2 | M11: 6.74 | N11: 2194.62 | O11: 29.277392 | P11: 29.7 | Q11: 21.6 | R11: 10.2 | S11: 10.4 | T11: 0.043 | U11: 0.0464 | V11: 3.5913
A12: 0.9758 | B12: MegaP_hMMP2_GluC-1_OS_QStar-XL_20111027.01916.01916.2 | C12: 1916 | D12: 12/20 | E12: F.n[89.01]SK[156.13]APGSAGHYE.L | F12: sp|P35250|RFC2_HUMAN | G12: 1218.5337 | H12: 1046 | I12: 2 | J12: 1218.5468 | K12: 610.2741 | L12: Replication factor C subunit 2 OS=Homo sapiens GN=RFC2 PE=1 SV=3 | M12: 6.49 | N12: 2235.27 | O12: 10.732882 | P12: 32.7 | Q12: 26.1 | R12: 8.8 | S12: 8.6 | T12: 0.012 | U12: 0.0131 | V12: 3.5074
A13: 0.9891 | B13: MegaP_hMMP2_GluC-1_OS_QStar-XL_20111027.01932.01932.4 | C13: 1932 | D13: 7/108 | E13: D.n[29.04]LAARLAAARLNRDPGLAGG.P | F13: sp|Q02846|GUC2D_HUMAN | G13: 1890.0907 | H13: 422 | I13: 4 | J13: 1890.0504 | K13: 473.53 | L13: Retinal guanylyl cyclase 1 OS=Homo sapiens GN=GUCY2D PE=1 SV=2 | M13: 11.7 | N13: 2271.77 | O13: -21.276371 | P13: 20.5 | Q13: 17 | R13: 13.7 | S13: 7.4 | T13: 0.47 | U13: -0.0403 | V13: 1.3298
A14: 0.9989 | B14: MegaP_hMMP2_GluC-1_OS_QStar-XL_20111027.01956.01956.2 | C14: 1956 | D14: 10/22 | E14: E.n[29.04]HGIDPTGTYHGD.S | F14: sp|P04350|TBB4A_HUMAN,sp|P68371|TBB4B_HUMAN,sp|P07437|TBB5_HUMAN | G14: 1296.5737 | H14: 543 | I14: 2 | J14: 1296.586 | K14: 649.2941 | L14: Tubulin beta-4A chain OS=Homo sapiens GN=TUBB4A PE=1 SV=2 | M14: 5.22 | N14: 2330.17 | O14: 9.4718249 | P14: 28.4 | Q14: 18 | R14: 11.1 | S14: 8.5 | T14: 0.00098 | U14: 0.0123 | V14: 5.2913
A15: 0.9792 | B15: MegaP_hMMP2_GluC-1_OS_QStar-XL_20111027.01983.01983.2 | C15: 1983 | D15: 13/16 | E15: K.n[89.01]LQGK[156.13]PQSHE.L | F15: sp|Q8IVD9|NUDC3_HUMAN | G15: 1138.5441 | H15: 76 | I15: 2 | J15: 1138.5516 | K15: 570.2793 | L15: NudC domain-containing protein 3 OS=Homo sapiens GN=NUDCD3 PE=1 SV=3 | M15: 6.76 | N15: 2395.88 | O15: 6.5757253 | P15: 37.5 | Q15: 34.8 | R15: 10.4 | S15: 9.7 | T15: 0.0092 | U15: 0.0075 | V15: 3.2846
... A418: 0.9978 | B418: MegaP_hMMP2_GluC-2_OS_QStar-XL_20111027.05583.05583.2 | C418: 5583 | D418: 14/28 | E418: P.n[89.01]AC[160.03]ALLLLFPLTAQHE.N | F418: sp|P09936|UCHL1_HUMAN | G418: 1783.8997 | H418: 234 | I418: 2 | J418: 1784.1209 | K418: 892.9571 | L418: Ubiquitin carboxyl-terminal hydrolase isozyme L1 OS=Homo sapiens GN=UCHL1 PE=1 SV=2 | M418: 5.47 | N418: 7157.79 | O418: 123.85813 | P418: 42.4 | Q418: 28.4 | R418: 11.1 | S418: 10 | T418: 0.0003 | U418: 0.2212 | V418: 5.1152

Sheet MMP3-G
A1: Supplementary Table S2c: Human MMP3 cleavage sites identified by PICS in GluC-generated human proteome libraries | J1: back to index
A2: Peptides were identified by LC-MS/MS spectrum-to-sequence assignment with Mascot and X! Tandem, and further analysed by iProphet within TPP at a false-discovery rate of 1%. iProphet probability score, spectrum ID, peptide sequence, and scores by Mascot (ionscore, identity score, homology score) and X! Tandem (hyperscore, nextscore, bscore, yscore) are shown together with other peptide and peptide-spectrum match measures. One exemplary accession number of a matching UniProt protein entry is listed. K[156.13] denotes lysine labeled by heavy-dimethyl, C[160.03] and M[147.04] represent carbamidomethylated cysteine and oxidized methionine, respectively, and n[89.01] indicates thioacylated N-termini. Data were further processed and rendered non-redundant for generation of cleavage specificity profiles via WebPICS (http://clipserve.clip.ubc.ca/pics/) and iceLogo (http://iomics.ugent.be/icelogoserver/).
A3: ='MMP1-G'!A3 -> probability | B3: ='MMP1-G'!B3 -> spectrum | C3: ='MMP1-G'!C3 -> start scan | D3: ='MMP1-G'!D3 -> ions | E3: ='MMP1-G'!E3 -> peptide | F3: ='MMP1-G'!F3 -> protein | G3: ='MMP1-G'!G3 -> calculated neutral peptide mass | H3: ='MMP1-G'!H3 -> index | ... V3: ='MMP1-G'!V3 -> fval
A4: 0.9893 | B4: MegaP_hMMP3_GluC_AS_QStar-XL_20080308.01336.01336.4 | C4: 1336 | D4: 19/138 | E4: K.n[89.01]NAQK[156.13]SNQNGK[156.13]DSK[156.13]PSSTPRSK[156.13]GQE.S | F4: sp|P06748|NPM_HUMAN,sp|P06748-3|NPM_HUMAN | G4: 2772.3827 | H4: 262 | I4: 4 | J4: 2772.4139 | K4: 694.103 | L4: Nucleophosmin OS=Homo sapiens GN=NPM1 PE=1 SV=2 | M4: 10 | N4: 1413.34 | O4: 11.237525 | P4: 30.2 | Q4: 18.7 | R4: 7.2 | S4: 10.1 | T4: 0.0016 | U4: 0.0312 | V4: 4.3828
A5: 0.9997 | B5: MegaP_hMMP3_GluC_AS_QStar-XL_20080308.01359.01359.3 | C5: 1359 | D5: 15/48 | E5: D.n[29.04]YTK[156.13]HPAK[156.13]PDPSGE.C | F5: sp|Q16576|RBBP7_HUMAN,sp|Q16576-2|RBBP7_HUMAN | G5: 1509.7827 | H5: 263 | I5: 3 | J5: 1509.7843 | K5: 504.2682 | L5: Histone-binding protein RBBP7 OS=Homo sapiens GN=RBBP7 PE=1 SV=1 | M5: 6.77 | N5: 1455.34 | O5: 1.0576382 | P5: 36.3 | Q5: 24.3 | R5: 13.7 | S5: 11.5 | T5: 0.016 | U5: 0.0016 | V5: 4.3275
A6: 0.9995 | B6: MegaP_hMMP3_GluC_AS_QStar-XL_20080308.01360.01360.3 | C6: 1360 | D6: 15/48 | E6: D.n[29.04]YTK[156.13]HPSK[156.13]PDPSGE.C | F6: sp|Q09028|RBBP4_HUMAN,sp|Q09028-2|RBBP4_HUMAN,sp|Q09028-3|RBBP4_HUMAN,sp|Q09028-4|RBBP4_HUMAN | G6: 1525.7776 | H6: 264 | I6: 3 | J6: 1525.7788 | K6: 509.5998 | L6: Histone-binding protein RBBP4 OS=Homo sapiens GN=RBBP4 PE=1 SV=3 | M6: 6.77 | N6: 1455.34 | O6: 0.78492966 | P6: 36.8 | Q6: 27 | R6: 13.7 | S6: 11.3 | T6: 0.017 | U6: 0.0012 | V6: 3.9373
A7: 0.9977 | B7: MegaP_hMMP3_GluC_AS_QStar-XL_20080308.01367.01367.4 | C7: 1367 | D7: 18/102 | E7: Y.n[89.01]NC[160.03]GRGGHIAK[156.13]DC[160.03]K[156.13]EPK[156.13]RE.R | F7: sp|P62633|CNBP_HUMAN,sp|P62633-2|CNBP_HUMAN,sp|P62633-3|CNBP_HUMAN,sp|P62633-4|CNBP_HUMAN,sp|P62633-5|CNBP_HUMAN,sp|P62633-6|CNBP_HUMAN | G7: 2283.1037 | H7: 265 | I7: 4 | J7: 2283.1215 | K7: 571.7832 | L7: Cellular nucleic acid-binding protein OS=Homo sapiens GN=CNBP PE=1 SV=1 | M7: 8.86 | N7: 1470.04 | O7: 7.7826701 | P7: 34.5 | Q7: 21.8 | R7: 11.4 | S7: 13.5 | T7: 0.0037 | U7: 0.0178 | V7: 4.5749
A8: 0.9986 | B8: MegaP_hMMP3_GluC_AS_QStar-XL_20080308.01371.01371.4 | C8: 1371 | D8: 22/84 | E8: A.n[89.01]QK[156.13]GQK[156.13]APAQK[156.13]APAPK[156.13].A | F8: sp|P50914|RL14_HUMAN | G8: 1747.0177 | H8: 656 | I8: 4 | J8: 1747.0341 | K8: 437.7617 | L8: 60S ribosomal protein L14 OS=Homo sapiens GN=RPL14 PE=1 SV=4 | M8: 10.48 | N8: 1477.39 | O8: 9.3658262 | P8: 38.3 | Q8: 27.6 | R8: 10.4 | S8: 12.5 | T8: 0.0031 | U8: 0.0164 | V8: 4.6256
A9: 0.9959 | B9: MegaP_hMMP3_GluC_AS_QStar-XL_20080308.01375.01375.3 | C9: 1375 | D9: 14/48 | E9: E.n[29.04]YRHPGASDRPQPT.A | F9: sp|O43660|PLRG1_HUMAN,sp|O43660-2|PLRG1_HUMAN | G9: 1508.7484 | H9: 266 | I9: 3 | J9: 1508.7582 | K9: 503.9234 | L9: Pleiotropic regulator 1 OS=Homo sapiens GN=PLRG1 PE=1 SV=1 | M9: 8.75 | N9: 1484.74 | O9: 6.4824667 | P9: 32.3 | Q9: 24 | R9: 12.1 | S9: 11.4 | T9: 0.0056 | U9: 0.0098 | V9: 4.5015
A10: 0.996 | B10: MegaP_hMMP3_GluC_AS_QStar-XL_20080308.01383.01383.4 | C10: 1383 | D10: 25/102 | E10: A.n[89.01]QK[156.13]GQK[156.13]APAQK[156.13]APAPK[156.13]ASG.K | F10: sp|P50914|RL14_HUMAN | G10: 1962.1084 | H10: 658 | I10: 4 | J10: 1962.1146 | K10: 491.5344 | L10: 60S ribosomal protein L14 OS=Homo sapiens GN=RPL14 PE=1 SV=4 | M10: 10.48 | N10: 1499.44 | O10: 3.1533907 | P10: 44.3 | Q10: 33.5 | R10: 11.6 | S10: 12.8 | T10: 0.0036 | U10: 0.0062 | V10: 4.0018
A11: 0.9956 | B11: MegaP_hMMP3_GluC_AS_QStar-XL_20080308.01419.01419.3 | C11: 1419 | D11: 12/40 | E11: E.n[29.04]HSVNYK[156.13]PPAQK[156.13].S | F11: sp|P52565|GDIR1_HUMAN,sp|P52565-2|GDIR1_HUMAN | G11: 1351.7607 | H11: 269 | I11: 3 | J11: 1351.7731 | K11: 451.5942 | L11: Rho GDP-dissociation inhibitor 1 OS=Homo sapiens GN=ARHGDIA PE=1 SV=3 | M11: 9.7 | N11: 1565.6 | O11: 9.15276 | P11: 26 | Q11: 17.3 | R11: 8 | S11: 10.7 | T11: 0.024 | U11: 0.0124 | V11: 4.4669
A12: 0.9994 | B12: MegaP_hMMP3_GluC_AS_QStar-XL_20080308.01427.01427.3 | C12: 1427 | D12: 14/44 | E12: E.n[29.04]K[156.13]K[156.13]YHNVGLSK[156.13]C[160.03]E.L | F12: sp|Q14103|HNRPD_HUMAN,sp|Q14103-2|HNRPD_HUMAN,sp|Q14103-3|HNRPD_HUMAN,sp|Q14103-4|HNRPD_HUMAN | G12: 1573.865 | H12: 631 | I12: 3 | J12: 1573.8606 | K12: 525.6289 | L12: Heterogeneous nuclear ribonucleoprotein D0 OS=Homo sapiens GN=HNRNPD PE=1 SV=1 | M12: 9.11 | N12: 1582.4 | O12: -2.7903083 | P12: 34.4 | Q12: 27.9 | R12: 9.6 | S12: 10.5 | T12: 0.0028 | U12: -0.0044 | V12: 4.6847
A13: 0.9994 | B13: MegaP_hMMP3_GluC_AS_QStar-XL_20080308.01428.01428.2 | C13: 1428 | D13: 16/26 | E13: T.n[89.01]QQQQPQQQRGAAK[156.13]E.A | F13: sp|Q00839|HNRPU_HUMAN,sp|Q00839-2|HNRPU_HUMAN | G13: 1739.8377 | H13: 270 | I13: 2 | J13: 1739.816 | K13: 870.9261 | L13: Heterogeneous nuclear ribonucleoprotein U OS=Homo sapiens GN=HNRNPU PE=1 SV=6 | M13: 8.75 | N13: 1580.3 | O13: -12.458003 | P13: 53.6 | Q13: 30.7 | R13: 10.6 | S13: 12.9 | T13: 6.9e-06 | U13: -0.0217 | V13: 7.3088
A14: 0.9805 | B14: MegaP_hMMP3_GluC_AS_QStar-XL_20080308.01444.01444.2 | C14: 1444 | D14: 11/22 | E14: E.n[89.01]GAAGQQPTAPDK[156.13].S | F14: sp|O95436|NPT2B_HUMAN,sp|O95436-2|NPT2B_HUMAN | G14: 1255.5867 | H14: 512 | I14: 2 | J14: 1255.5719 | K14: 628.8006 | L14: Sodium-dependent phosphate transport protein 2B OS=Homo sapiens GN=SLC34A2 PE=1 SV=3 | M14: 5.84 | N14: 1613.9 | O14: -11.768437 | P14: 32.7 | Q14: 26.2 | R14: 10.6 | S14: 12.4 | T14: 0.054 | U14: -0.0148 | V14: 2.6662
A15: 0.9999 | B15: MegaP_hMMP3_GluC_AS_QStar-XL_20080308.01463.01463.3 | C15: 1463 | D15: 16/40 | E15: E.n[29.04]TSHNYHK[156.13]FDSE.Y | F15: sp|P43243|MATR3_HUMAN | G15: 1419.6419 | H15: 272 | I15: 3 | J15: 1419.6518 | K15: 474.2212 | L15: Matrin-3 OS=Homo sapiens GN=MATR3 PE=1 SV=2 | M15: 5.96 | N15: 1646.45 | O15: 6.9587779 | P15: 34.5 | Q15: 21.8 | R15: 9.4 | S15: 10.3 | T15: 0.0032 | U15: 0.0099 | V15: 5.8839
... A284: 0.9953 | B284: MegaP_hMMP3_GluC_AS_QStar-XL_20080308.04755.04755.2 | C284: 4755 | D284: 14/22 | E284: G.n[89.01]LQVLNDYLADK[156.13]S.Y | F284: sp|P24534|EF1B_HUMAN | G284: 1493.7437 | H284: 865 | I284: 2 | J284: 1493.7279 | K284: 747.8791 | L284: Elongation factor 1-beta OS=Homo sapiens GN=EEF1B2 PE=1 SV=3 | M284: 4.21 | N284: 7083.1 | O284: -10.563205 | P284: 42.9 | Q284: 28.2 | R284: 11.6 | S284: 10.6 | T284: 0.0016 | U284: -0.0158 | V284: 4.9561

Sheet MMP7-G
A1: Supplementary Table S2d: Human MMP7 cleavage sites identified by PICS in GluC-generated human proteome libraries | J1: back to index
A2: Peptides were identified by LC-MS/MS spectrum-to-sequence assignment with Mascot and X! Tandem, and further analysed by iProphet within TPP at a false-discovery rate of 1%. iProphet probability score, spectrum ID, peptide sequence, and scores by Mascot (ionscore, identity score, homology score) and X! Tandem (hyperscore, nextscore, bscore, yscore) are shown together with other peptide and peptide-spectrum match measures. One exemplary accession number of a matching UniProt protein entry is listed. K[156.13] denotes lysine labeled by heavy-dimethyl, C[160.03] and M[147.04] represent carbamidomethylated cysteine and oxidized methionine, respectively, and n[89.01] indicates thioacylated N-termini. Data were further processed and rendered non-redundant for generation of cleavage specificity profiles via WebPICS (http://clipserve.clip.ubc.ca/pics/) and iceLogo (http://iomics.ugent.be/icelogoserver/).
A3: ='MMP1-G'!A3 -> probability | B3: ='MMP1-G'!B3 -> spectrum | C3: ='MMP1-G'!C3 -> start scan | D3: ='MMP1-G'!D3 -> ions | E3: ='MMP1-G'!E3 -> peptide | F3: ='MMP1-G'!F3 -> protein | G3: ='MMP1-G'!G3 -> calculated neutral peptide mass | H3: ='MMP1-G'!H3 -> index | ... V3: ='MMP1-G'!V3 -> fval
A4: 0.9925 | B4: MegaP_hMMP7_GluC_OS_QStar-Pulsar_20080108.01171.01171.3 | C4: 1171 | D4: 11/44 | E4: P.n[29.04]EVK[156.13]HGYK[156.13]LNK[156.13]TH.S | F4: sp|P20023|CR2_HUMAN | G4: 1564.9087 | H4: 1007 | I4: 3 | J4: 1566.0462 | K4: 522.6435 | L4: Complement receptor type 2 OS=Homo sapiens GN=CR2 PE=1 SV=2 | M4: 9.53 | N4: 1279.88 | O4: 85.55545 | P4: 33.2 | Q4: 23.3 | R4: 11.1 | S4: 12 | T4: 0.0019 | U4: 1.1375 | V4: 5.5392
A5: 0.9955 | B5: MegaP_hMMP7_GluC_OS_QStar-Pulsar_20080108.01284.01284.3 | C5: 1284 | D5: 17/80 | E5: K.n[29.04]APK[156.13]PDGPGGGPGGSHMGGNYG.D | F5: sp|P35637|FUS_HUMAN | G5: 1921.8737 | H5: 728 | I5: 3 | J5: 1921.9732 | K5: 641.6318 | L5: RNA-binding protein FUS OS=Homo sapiens GN=FUS PE=1 SV=1 | M5: 6.79 | N5: 1552.39 | O5: 51.69112 | P5: 37.1 | Q5: 27.7 | R5: 10.2 | S5: 8 | T5: 0.0019 | U5: 0.0995 | V5: 4.0405
A6: 0.9761 | B6: MegaP_hMMP7_GluC_OS_QStar-Pulsar_20080108.01341.01341.3 | C6: 1341 | D6: 15/72 | E6: Q.n[89.01]LK[156.13]GQSQTSPDHRSDTSSPE.V | F6: sp|Q9UQ35|SRRM2_HUMAN | G6: 2171.9757 | H6: 1014 | I6: 3 | J6: 2172.1361 | K6: 724.9992 | L6: Serine\arginine repetitive matrix protein 2 OS=Homo sapiens GN=SRRM2 PE=1 SV=2 | M6: 5.54 | N6: 1702.4 | O6: 73.747208 | P6: 35 | Q6: 26.1 | R6: 10.5 | S6: 11.2 | T6: 0.011 | U6: 0.1604 | V6: 3.436
A7: 0.9561 | B7: MegaP_hMMP7_GluC_OS_QStar-Pulsar_20080108.01391.01391.2 | C7: 1391 | D7: 12/24 | E7: L.n[89.01]QTVAK[156.13]NK[156.13]DQGTYE.D | F7: sp|P60660|MYL6_HUMAN,sp|P60660-2|MYL6_HUMAN | G7: 1624.7767 | H7: 244 | I7: 2 | J7: 1624.8628 | K7: 813.3956 | L7: Myosin light polypeptide 6 OS=Homo sapiens GN=MYL6 PE=1 SV=2 | M7: 6.24 | N7: 1831.65 | O7: 52.926276 | P7: 34.1 | Q7: 25.2 | R7: 10.8 | S7: 8.5 | T7: 0.014 | U7: 0.0861 | V7: 3.4525
A8: 0.9761 | B8: MegaP_hMMP7_GluC_OS_QStar-Pulsar_20080108.01416.01416.3 | C8: 1416 | D8: 13/40 | E8: D.n[89.01]K[156.13]PK[156.13]VQVSYK[156.13]GE.T | F8: sp|P08107|HSP71_HUMAN | G8: 1433.7947 | H8: 394 | I8: 3 | J8: 1433.9012 | K8: 478.9388 | L8: Heat shock 70 kDa protein 1A\1B OS=Homo sapiens GN=HSPA1A PE=1 SV=5 | M8: 9.53 | N8: 1887.83 | O8: 74.122205 | P8: 31.1 | Q8: 24.1 | R8: 10.2 | S8: 11.2 | T8: 0.031 | U8: 0.1065 | V8: 3.652
A9: 0.9675 | B9: MegaP_hMMP7_GluC_OS_QStar-Pulsar_20080108.01442.01442.3 | C9: 1442 | D9: 12/64 | E9: D.n[89.01]VRRGNVAGDSK[156.13]NDPPME.A | F9: sp|P68104|EF1A1_HUMAN,sp|Q5VTE0|EF1A3_HUMAN | G9: 1956.9147 | H9: 663 | I9: 3 | J9: 1957.0289 | K9: 653.3122 | L9: Elongation factor 1-alpha 1 OS=Homo sapiens GN=EEF1A1 PE=1 SV=1 | M9: 6.24 | N9: 1963.99 | O9: 58.267191 | P9: 29.8 | Q9: 21.7 | R9: 13 | S9: 14 | T9: 0.019 | U9: 0.1142 | V9: 3.441
A10: 0.9995 | B10: MegaP_hMMP7_GluC_OS_QStar-Pulsar_20080108.01471.01471.3 | C10: 1471 | D10: 15/48 | E10: F.n[29.04]SLEDPQTHSNRIY.R | F10: sp|P08238|HS90B_HUMAN | G10: 1586.7687 | H10: 732 | I10: 3 | J10: 1586.8859 | K10: 529.9302 | L10: Heat shock protein HSP 90-beta OS=Homo sapiens GN=HSP90AB1 PE=1 SV=4 | M10: 5.3 | N10: 2033.69 | O10: 73.720401 | P10: 41 | Q10: 28.7 | R10: 13.6 | S10: 14 | T10: 0.00087 | U10: 0.1172 | V10: 5.7731
A11: 0.9981 | B11: MegaP_hMMP7_GluC_OS_QStar-Pulsar_20080108.01480.01480.2 | C11: 1480 | D11: 9/20 | E11: T.n[89.01]SQHSNTQTLGK[156.13].- | F11: sp|Q6PKG0|LARP1_HUMAN | G11: 1315.6187 | H11: 927 | I11: 2 | J11: 1315.3932 | K11: 658.8166 | L11: La-related protein 1 OS=Homo sapiens GN=LARP1 PE=1 SV=2 | M11: 8.49 | N11: 2063.92 | O11: -171.14019 | P11: 29.1 | Q11: 22.4 | R11: 5.3 | S11: 10.6 | T11: 0.0054 | U11: -0.2255 | V11: 4.0296
A12: 0.9732 | B12: MegaP_hMMP7_GluC_OS_QStar-Pulsar_20080108.01484.01484.3 | C12: 1484 | D12: 12/84 | E12: H.n[89.01]MVANC[160.03]PHK[156.13]NVAQPPASSQGRQE.A | F12: sp|Q6ZN17|LN28B_HUMAN,sp|Q6ZN17-2|LN28B_HUMAN | G12: 2521.1627 | H12: 400 | I12: 3 | J12: 2521.3906 | K12: 841.3948 | L12: Protein lin-28 homolog B OS=Homo sapiens GN=LIN28B PE=1 SV=1 | M12: 8 | N12: 2064.95 | O12: 90.286589 | P12: 31.2 | Q12: 21.1 | R12: 10.6 | S12: 12.9 | T12: 0.017 | U12: 0.2279 | V12: 3.3177
A13: 0.9987 | B13: MegaP_hMMP7_GluC_OS_QStar-Pulsar_20080108.01498.01498.2 | C13: 1498 | D13: 15/18 | E13: E.n[29.04]GYGPPPPHYE.G | F13: sp|P14866|HNRPL_HUMAN,sp|P14866-2|HNRPL_HUMAN | G13: 1140.5237 | H13: 246 | I13: 2 | J13: 1140.5758 | K13: 571.2691 | L13: Heterogeneous nuclear ribonucleoprotein L OS=Homo sapiens GN=HNRNPL PE=1 SV=2 | M13: 5.47 | N13: 2109.88 | O13: 45.600226 | P13: 47.7 | Q13: 29.7 | R13: 9.9 | S13: 11 | T13: 0.00025 | U13: 0.0521 | V13: 6.5058
A14: 0.9999 | B14: MegaP_hMMP7_GluC_OS_QStar-Pulsar_20080108.01504.01504.3 | C14: 1504 | D14: 14/48 | E14: F.n[29.04]SLEDPQTHANRIY.R | F14: sp|P07900|HS90A_HUMAN | G14: 1570.7737 | H14: 1096 | I14: 3 | J14: 1570.8813 | K14: 524.5985 | L14: Heat shock protein HSP 90-alpha OS=Homo sapiens GN=HSP90AA1 PE=1 SV=5 | M14: 5.3 | N14: 2117.05 | O14: 68.369747 | P14: 37.4 | Q14: 23 | R14: 13 | S14: 13.6 | T14: 1.7e-05 | U14: 0.1076 | V14: 8.4276
A15: 0.9872 | B15: MegaP_hMMP7_GluC_OS_QStar-Pulsar_20080108.01512.01512.2 | C15: 1512 | D15: 11/26 | E15: Q.n[89.01]LHAHQPQPATTPTG.S | F15: sp|Q8WWM7|ATX2L_HUMAN | G15: 1542.7247 | H15: 736 | I15: 2 | J15: 1542.8318 | K15: 772.3696 | L15: Ataxin-2-like protein OS=Homo sapiens GN=ATXN2L PE=1 SV=2 | M15: 6.92 | N15: 2137.9 | O15: 69.332092 | P15: 32.9 | Q15: 23.9 | R15: 12.7 | S15: 10.6 | T15: 0.0028 | U15: 0.1071 | V15: 4.0834
... A305: 0.9942 | B305: MegaP_hMMP7_GluC_OS_QStar-Pulsar_20080108.04610.04610.3 | C305: 4610 | D305: 15/52 | E305: Q.n[89.01]LK[156.13]K[156.13]SADTLWDIQK[156.13]D.L | F305: sp|P07195|LDHB_HUMAN | G305: 1831.9757 | H305: 237 | I305: 3 | J305: 1833.1604 | K305: 611.6658 | L305: L-lactate dehydrogenase B chain OS=Homo sapiens GN=LDHB PE=1 SV=2 | M305: 6.17 | N305: 6330.74 | O305: 98.825753 | P305: 36.7 | Q305: 25.4 | R305: 9.9 | S305: 10.5 | T305: 0.00073 | U305: 1.1847 | V305: 5.7064

Sheet MMP8-G
A1: Supplementary Table S2e: Human MMP8 cleavage sites identified by PICS in GluC-generated human proteome libraries | J1: back to index
A2: Peptides were identified by LC-MS/MS spectrum-to-sequence assignment with Mascot and X! Tandem, and further analysed by iProphet within TPP at a false-discovery rate of 1%. iProphet probability score, spectrum ID, peptide sequence, and scores by Mascot (ionscore, identity score, homology score) and X! Tandem (hyperscore, nextscore, bscore, yscore) are shown together with other peptide and peptide-spectrum match measures. One exemplary accession number of a matching UniProt protein entry is listed. K[156.13] denotes lysine labeled by heavy-dimethyl, C[160.03] and M[147.04] represent carbamidomethylated cysteine and oxidized methionine, respectively, and n[89.01] indicates thioacylated N-termini. Data were further processed and rendered non-redundant for generation of cleavage specificity profiles via WebPICS (http://clipserve.clip.ubc.ca/pics/) and iceLogo (http://iomics.ugent.be/icelogoserver/).
A3: ='MMP1-G'!A3 -> probability | B3: ='MMP1-G'!B3 -> spectrum | C3: ='MMP1-G'!C3 -> start scan | D3: ='MMP1-G'!D3 -> ions | E3: ='MMP1-G'!E3 -> peptide | F3: ='MMP1-G'!F3 -> protein | G3: ='MMP1-G'!G3 -> calculated neutral peptide mass | H3: ='MMP1-G'!H3 -> index | ... V3: ='MMP1-G'!V3 -> fval
A4: 0.9999 | B4: MegaP_hMMP8_GluC_JC_QStar-XL_20080502.01563.01563.4 | C4: 1563 | D4: 17/120 | E4: A.n[89.01]QK[156.13]GQK[156.13]APAQK[156.13]APAPK[156.13]ASGK[156.13]K[156.13]A.- | F4: sp|P50914|RL14_HUMAN | G4: 2345.3977 | H4: 1022 | I4: 4 | J4: 2345.4245 | K4: 587.3567 | L4: 60S ribosomal protein L14 OS=Homo sapiens GN=RPL14 PE=1 SV=4 | M4: 10.7 | N4: 1671.62 | O4: 11.407038 | P4: 36.1 | Q4: 27.5 | R4: 11.4 | S4: 11.7 | T4: 0.022 | U4: 0.0268 | V4: 2.9055
A5: 0.9986 | B5: MegaP_hMMP8_GluC_JC_QStar-XL_20080502.01632.01632.3 | C5: 1632 | D5: 15/48 | E5: D.n[29.04]YTK[156.13]HPAK[156.13]PDPSGE.C | F5: sp|Q16576|RBBP7_HUMAN,sp|Q16576-2|RBBP7_HUMAN | G5: 1509.7827 | H5: 345 | I5: 3 | J5: 1509.7936 | K5: 504.2682 | L5: Histone-binding protein RBBP7 OS=Homo sapiens GN=RBBP7 PE=1 SV=1 | M5: 6.77 | N5: 1752.47 | O5: 7.2051605 | P5: 36 | Q5: 24 | R5: 13.7 | S5: 10 | T5: 0.013 | U5: 0.0109 | V5: 4.458
A6: 0.9991 | B6: MegaP_hMMP8_GluC_JC_QStar-XL_20080502.01634.01634.3 | C6: 1634 | D6: 16/48 | E6: G.n[29.04]K[156.13]APGTPHSHTK[156.13]PY.V | F6: sp|Q07020|RL18_HUMAN | G6: 1503.8198 | H6: 714 | I6: 3 | J6: 1503.8279 | K6: 502.2805 | L6: 60S ribosomal protein L18 OS=Homo sapiens GN=RPL18 PE=1 SV=2 | M6: 9.7 | N6: 1755.62 | O6: 5.3754824 | P6: 37.7 | Q6: 24.7 | R6: 7.4 | S6: 9.9 | T6: 0.00073 | U6: 0.0081 | V6: 6.1191
A7: 0.9976 | B7: MegaP_hMMP8_GluC_JC_QStar-XL_20080502.01638.01638.3 | C7: 1638 | D7: 13/48 | E7: D.n[29.04]YTK[156.13]HPSK[156.13]PDPSGE.C | F7: sp|Q09028|RBBP4_HUMAN,sp|Q09028-2|RBBP4_HUMAN,sp|Q09028-3|RBBP4_HUMAN,sp|Q09028-4|RBBP4_HUMAN | G7: 1525.7777 | H7: 58 | I7: 3 | J7: 1525.7968 | K7: 509.5998 | L7: Histone-binding protein RBBP4 OS=Homo sapiens GN=RBBP4 PE=1 SV=3 | M7: 6.77 | N7: 1760.87 | O7: 12.493464 | P7: 30.1 | Q7: 21.6 | R7: 13.6 | S7: 10.4 | T7: 0.019 | U7: 0.0191 | V7: 3.9649
A8: 0.9994 | B8: MegaP_hMMP8_GluC_JC_QStar-XL_20080502.01655.01655.3 | C8: 1655 | D8: 14/48 | E8: D.n[29.04]YTK[156.13]HPAK[156.13]PDPSGE.C | F8: sp|Q16576|RBBP7_HUMAN,sp|Q16576-2|RBBP7_HUMAN | G8: 1509.7827 | H8: 346 | I8: 3 | J8: 1509.7873 | K8: 504.2682 | L8: Histone-binding protein RBBP7 OS=Homo sapiens GN=RBBP7 PE=1 SV=1 | M8: 6.77 | N8: 1782.92 | O8: 3.04071 | P8: 33.2 | Q8: 26.8 | R8: 13.6 | S8: 10.1 | T8: 0.0012 | U8: 0.0046 | V8: 4.9999
A9: 0.9994 | B9: MegaP_hMMP8_GluC_JC_QStar-XL_20080502.01752.01752.3 | C9: 1752 | D9: 17/56 | E9: N.n[89.01]QNQTQHK[156.13]QRPQATAE.Q | F9: sp|Q14157|UBP2L_HUMAN,sp|Q14157-1|UBP2L_HUMAN,sp|Q14157-3|UBP2L_HUMAN,sp|Q14157-4|UBP2L_HUMAN,sp|Q14157-5|UBP2L_HUMAN | G9: 1879.8957 | H9: 347 | I9: 3 | J9: 1879.914 | K9: 627.6392 | L9: Ubiquitin-associated protein 2-like OS=Homo sapiens GN=UBAP2L PE=1 SV=2 | M9: 8.76 | N9: 1907.87 | O9: 9.7189596 | P9: 38.9 | Q9: 24.9 | R9: 10 | S9: 10.9 | T9: 0.00052 | U9: 0.0183 | V9: 5.9633
A10: 0.9864 | B10: MegaP_hMMP8_GluC_JC_QStar-XL_20080502.01772.01772.4 | C10: 1772 | D10: 23/102 | E10: A.n[89.01]QK[156.13]GQK[156.13]APAQK[156.13]APAPK[156.13]ASG.K | F10: sp|P50914|RL14_HUMAN | G10: 1962.1087 | H10: 717 | I10: 4 | J10: 1962.1351 | K10: 491.5345 | L10: 60S ribosomal protein L14 OS=Homo sapiens GN=RPL14 PE=1 SV=4 | M10: 10.48 | N10: 1938.32 | O10: 13.427338 | P10: 41.5 | Q10: 33.2 | R10: 10.7 | S10: 12.6 | T10: 0.011 | U10: 0.0264 | V10: 3.2688
A11: 0.9775 | B11: MegaP_hMMP8_GluC_JC_QStar-XL_20080502.01824.01824.4 | C11: 1824 | D11: 17/78 | E11: P.n[89.01]VK[156.13]GK[156.13]GK[156.13]VGRPTASK[156.13].A | F11: sp|Q9H1E3|NUCKS_HUMAN | G11: 1611.9857 | H11: 720 | I11: 4 | J11: 1612.0099 | K11: 404.0037 | L11: Nuclear ubiquitous casein and cyclin-dependent kinase substrate 1 OS=Homo sapiens GN=NUCKS1 PE=1 SV=1 | M11: 11.33 | N11: 2017.07 | O11: 14.97511 | P11: 34.9 | Q11: 27.7 | R11: 9.8 | S11: 11.5 | T11: 0.041 | U11: 0.0242 | V11: 3.0101
A12: 0.9756 | B12: MegaP_hMMP8_GluC_JC_QStar-XL_20080502.01831.01831.3 | C12: 1831 | D12: 11/44 | E12: E.n[29.04]K[156.13]K[156.13]YHNVGLSK[156.13]C[160.03]E.L | F12: sp|Q14103|HNRPD_HUMAN,sp|Q14103-2|HNRPD_HUMAN,sp|Q14103-3|HNRPD_HUMAN,sp|Q14103-4|HNRPD_HUMAN | G12: 1573.865 | H12: 59 | I12: 3 | J12: 1573.8619 | K12: 525.6289 | L12: Heterogeneous nuclear ribonucleoprotein D0 OS=Homo sapiens GN=HNRNPD PE=1 SV=1 | M12: 9.11 | N12: 2030.72 | O12: -1.965899 | P12: 25.4 | Q12: 22.1 | R12: 7.2 | S12: 7.3 | T12: 0.056 | U12: -0.0031 | V12: 2.6143
A13: 0.964 | B13: MegaP_hMMP8_GluC_JC_QStar-XL_20080502.01837.01837.3 | C13: 1837 | D13: 12/52 | E13: E.n[29.04]YRHPGASDRPQPTA.M | F13: sp|O43660|PLRG1_HUMAN,sp|O43660-2|PLRG1_HUMAN | G13: 1579.7855 | H13: 350 | I13: 3 | J13: 1579.7824 | K13: 527.6024 | L13: Pleiotropic regulator 1 OS=Homo sapiens GN=PLRG1 PE=1 SV=1 | M13: 8.75 | N13: 2041.22 | O13: -1.9585456 | P13: 26.4 | Q13: 18.8 | R13: 12.2 | S13: 11 | T13: 0.025 | U13: -0.0031 | V13: 3.7106
A14: 0.9993 | B14: MegaP_hMMP8_GluC_JC_QStar-XL_20080502.01849.01849.3 | C14: 1849 | D14: 13/44 | E14: E.n[29.04]VFK[156.13]K[156.13]HGVYNPNK[156.13].L | F14: sp|P40926|MDHM_HUMAN | G14: 1541.9082 | H14: 351 | I14: 3 | J14: 1541.9127 | K14: 514.9767 | L14: Malate dehydrogenase, mitochondrial OS=Homo sapiens GN=MDH2 PE=1 SV=3 | M14: 10 | N14: 2059.07 | O14: 2.9127531 | P14: 31.8 | Q14: 21.5 | R14: 8.3 | S14: 10.3 | T14: 0.0013 | U14: 0.0045 | V14: 5.9068
A15: 0.9969 | B15: MegaP_hMMP8_GluC_JC_QStar-XL_20080502.01883.01883.3 | C15: 1883 | D15: 16/40 | E15: E.n[29.04]TSHNYHK[156.13]FDSE.Y | F15: sp|P43243|MATR3_HUMAN | G15: 1419.6417 | H15: 60 | I15: 3 | J15: 1419.6536 | K15: 474.2212 | L15: Matrin-3 OS=Homo sapiens GN=MATR3 PE=1 SV=2 | M15: 5.96 | N15: 2116.87 | O15: 8.3645916 | P15: 32.8 | Q15: 22.9 | R15: 8.4 | S15: 9.7 | T15: 0.019 | U15: 0.0119 | V15: 4.4101
... A221: 0.9834 | B221: MegaP_hMMP8_GluC_JC_QStar-XL_20080502.05850.05850.2 | C221: 5850 | D221: 13/18 | E221: N.n[89.01]IIFLSDQTK[156.13]E.K | F221: sp|Q04837|SSBP_HUMAN | G221: 1308.6637 | H221: 343 | I221: 2 | J221: 1308.6867 | K221: 655.3391 | L221: Single-stranded DNA-binding protein, mitochondrial OS=Homo sapiens GN=SSBP1 PE=1 SV=1 | M221: 4.75 | N221: 8611.11 | O221: 17.548167 | P221: 40.2 | Q221: 35.4 | R221: 11.9 | S221: 10.2 | T221: 0.0049 | U221: 0.023 | V221: 3.6951

Sheet MMP9-G
A1: Supplementary Table S2f: Human MMP9 cleavage sites identified by PICS in GluC-generated human proteome libraries | J1: back to index
A2: Peptides were identified by LC-MS/MS spectrum-to-sequence assignment with Mascot and X! Tandem, and further analysed by iProphet within TPP at a false-discovery rate of 1%. iProphet probability score, spectrum ID, peptide sequence, and scores by Mascot (ionscore, identity score, homology score) and X! Tandem (hyperscore, nextscore, bscore, yscore) are shown together with other peptide and peptide-spectrum match measures. One exemplary accession number of a matching UniProt protein entry is listed. K[156.13] denotes lysine labeled by heavy-dimethyl, C[160.03] and M[147.04] represent carbamidomethylated cysteine and oxidized methionine, respectively, and n[89.01] indicates thioacylated N-termini. Data were further processed and rendered non-redundant for generation of cleavage specificity profiles via WebPICS (http://clipserve.clip.ubc.ca/pics/) and iceLogo (http://iomics.ugent.be/icelogoserver/).
A3: ='MMP1-G'!A3 -> probability | B3: ='MMP1-G'!B3 -> spectrum | C3: ='MMP1-G'!C3 -> start scan | D3: ='MMP1-G'!D3 -> ions | E3: ='MMP1-G'!E3 -> peptide | F3: ='MMP1-G'!F3 -> protein | G3: ='MMP1-G'!G3 -> calculated neutral peptide mass | H3: ='MMP1-G'!H3 -> index | ... V3: ='MMP1-G'!V3 -> fval
A4: 1 | B4: MegaP_hMMP9_GluC_AP_QStar-XL_20080502.01573.01573.4 | C4: 1573 | D4: 21/120 | E4: A.n[89.01]QK[156.13]GQK[156.13]APAQK[156.13]APAPK[156.13]ASGK[156.13]K[156.13]A.- | F4: sp|P50914|RL14_HUMAN | G4: 2345.3981 | H4: 485 | I4: 4 | J4: 2345.4011 | K4: 587.3568 | L4: 60S ribosomal protein L14 OS=Homo sapiens GN=RPL14 PE=1 SV=4 | M4: 10.7 | N4: 1668.46 | O4: 1.276907 | P4: 40 | Q4: 22.5 | R4: 8.9 | S4: 9.5 | T4: 3.6e-06 | U4: 0.003 | V4: 7.5799
A5: 0.9982 | B5: MegaP_hMMP9_GluC_AP_QStar-XL_20080502.01606.01606.3 | C5: 1606 | D5: 15/48 | E5: A.n[89.01]QK[156.13]APAPK[156.13]ASGK[156.13]K[156.13]A.- | F5: sp|P50914|RL14_HUMAN | G5: 1480.8797 | H5: 486 | I5: 3 | J5: 1480.9012 | K5: 494.6338 | L5: 60S ribosomal protein L14 OS=Homo sapiens GN=RPL14 PE=1 SV=4 | M5: 10.48 | N5: 1706.26 | O5: 14.488833 | P5: 32.8 | Q5: 20.1 | R5: 10.4 | S5: 11.5 | T5: 0.0033 | U5: 0.0215 | V5: 5.5172
A6: 0.999 | B6: MegaP_hMMP9_GluC_AP_QStar-XL_20080502.01646.01646.3 | C6: 1646 | D6: 13/48 | E6: D.n[29.04]YTK[156.13]HPAK[156.13]PDPSGE.C | F6: sp|Q16576|RBBP7_HUMAN,sp|Q16576-2|RBBP7_HUMAN | G6: 1509.7827 | H6: 487 | I6: 3 | J6: 1509.8245 | K6: 504.2682 | L6: Histone-binding protein RBBP7 OS=Homo sapiens GN=RBBP7 PE=1 SV=1 | M6: 6.77 | N6: 1749.31 | O6: 27.630799 | P6: 31.8 | Q6: 24.4 | R6: 13.5 | S6: 11.5 | T6: 0.0021 | U6: 0.0418 | V6: 4.911
A7: 0.9975 | B7: MegaP_hMMP9_GluC_AP_QStar-XL_20080502.01654.01654.3 | C7: 1654 | D7: 15/48 | E7: G.n[29.04]K[156.13]APGTPHSHTK[156.13]PY.V | F7: sp|Q07020|RL18_HUMAN | G7: 1503.8198 | H7: 1005 | I7: 3 | J7: 1503.8227 | K7: 502.2805 | L7: 60S ribosomal protein L18 OS=Homo sapiens GN=RPL18 PE=1 SV=2 | M7: 9.7 | N7: 1758.76 | O7: 1.9245554 | P7: 35.9 | Q7: 26.7 | R7: 8.6 | S7: 11.3 | T7: 0.00084 | U7: 0.0029 | V7: 5.55
A8: 0.995 | B8: MegaP_hMMP9_GluC_AP_QStar-XL_20080502.01671.01671.3 | C8: 1671 | D8: 10/48 | E8: D.n[29.04]YTK[156.13]HPAK[156.13]PDPSGE.C | F8: sp|Q16576|RBBP7_HUMAN,sp|Q16576-2|RBBP7_HUMAN | G8: 1509.7827 | H8: 341 | I8: 3 | J8: 1509.8052 | K8: 504.2682 | L8: Histone-binding protein RBBP7 OS=Homo sapiens GN=RBBP7 PE=1 SV=1 | M8: 6.77 | N8: 1780.81 | O8: 14.873038 | P8: 26.9 | Q8: 20.8 | R8: 12.4 | S8: 11.1 | T8: 0.021 | U8: 0.0225 | V8: 3.6008
A9: 0.9554 | B9: MegaP_hMMP9_GluC_AP_QStar-XL_20080502.01763.01763.4 | C9: 1763 | D9: 22/102 | E9: A.n[89.01]QK[156.13]GQK[156.13]APAQK[156.13]APAPK[156.13]ASG.K | F9: sp|P50914|RL14_HUMAN | G9: 1962.1087 | H9: 1494 | I9: 4 | J9: 1962.1258 | K9: 491.5345 | L9: 60S ribosomal protein L14 OS=Homo sapiens GN=RPL14 PE=1 SV=4 | M9: 10.48 | N9: 1892.12 | O9: 8.6972532 | P9: 39.2 | Q9: 29.2 | R9: 12 | S9: 13.3 | T9: 0.0035 | U9: 0.0171 | V9: 4.0684
A10: 0.9558 | B10: MegaP_hMMP9_GluC_AP_QStar-XL_20080502.01788.01788.4 | C10: 1788 | D10: 24/102 | E10: A.n[89.01]QK[156.13]GQK[156.13]APAQK[156.13]APAPK[156.13]ASG.K | F10: sp|P50914|RL14_HUMAN | G10: 1962.1087 | H10: 1495 | I10: 4 | J10: 1962.1583 | K10: 491.5345 | L10: 60S ribosomal protein L14 OS=Homo sapiens GN=RPL14 PE=1 SV=4 | M10: 10.48 | N10: 1924.67 | O10: 25.22712 | P10: 42.9 | Q10: 35 | R10: 11.6 | S10: 13 | T10: 0.0017 | U10: 0.0496 | V10: 4.0743
A11: 0.9984 | B11: MegaP_hMMP9_GluC_AP_QStar-XL_20080502.01852.01852.3 | C11: 1852 | D11: 12/44 | E11: E.n[29.04]GGANPDAK[156.13]DHYE.A | F11: sp|O75832|PSD10_HUMAN,sp|O75832-2|PSD10_HUMAN | G11: 1328.5997 | H11: 344 | I11: 3 | J11: 1328.6118 | K11: 443.8738 | L11: 26S proteasome non-ATPase regulatory subunit 10 OS=Homo sapiens GN=PSMD10 PE=1 SV=1 | M11: 4.81 | N11: 2010.17 | O11: 9.0866668 | P11: 25.9 | Q11: 21.1 | R11: 11.2 | S11: 10.3 | T11: 0.0036 | U11: 0.0121 | V11: 4.5186
A12: 0.9956 | B12: MegaP_hMMP9_GluC_AP_QStar-XL_20080502.01919.01919.3 | C12: 1919 | D12: 15/40 | E12: E.n[29.04]TSHNYHK[156.13]FDSE.Y | F12: sp|P43243|MATR3_HUMAN | G12: 1419.6419 | H12: 852 | I12: 3 | J12: 1419.6487 | K12: 474.2212 | L12: Matrin-3 OS=Homo sapiens GN=MATR3 PE=1 SV=2 | M12: 5.96 | N12: 2109.02 | O12: 4.7797666 | P12: 32.9 | Q12: 22.4 | R12: 9.8 | S12: 10.9 | T12: 0.022 | U12: 0.0068 | V12: 4.4261
A13: 1 | B13: MegaP_hMMP9_GluC_AP_QStar-XL_20080502.01924.01924.3 | C13: 1924 | D13: 21/68 | E13: H.n[89.01]QQHHQGPPPGGPGGRSEE.K | F13: sp|P23246|SFPQ_HUMAN,sp|P23246-2|SFPQ_HUMAN | G13: 1938.8391 | H13: 853 | I13: 3 | J13: 1938.8415 | K13: 647.287 | L13: Splicing factor, proline- and glutamine-rich OS=Homo sapiens GN=SFPQ PE=1 SV=2 | M13: 6.04 | N13: 2118.47 | O13: 1.2359278 | P13: 50.8 | Q13: 25.8 | R13: 12.4 | S13: 12.4 | T13: 3.1e-07 | U13: 0.0024 | V13: 9.5847
A14: 0.994 | B14: MegaP_hMMP9_GluC_AP_QStar-XL_20080502.01987.01987.3 | C14: 1987 | D14: 15/40 | E14: F.n[29.04]K[156.13]YHHVGK[156.13]LLK[156.13]E.G | F14: sp|O00264|PGRC1_HUMAN | G14: 1462.9027 | H14: 226 | I14: 3 | J14: 1462.9209 | K14: 488.6415 | L14: Membrane-associated progesterone receptor component 1 OS=Homo sapiens GN=PGRMC1 PE=1 SV=3 | M14: 9.53 | N14: 2218.37 | O14: 12.415373 | P14: 32.3 | Q14: 21.9 | R14: 7.2 | S14: 9.8 | T14: 0.0054 | U14: 0.0182 | V14: 5.2902
A15: 0.9951 | B15: MegaP_hMMP9_GluC_AP_QStar-XL_20080502.02017.02017.2 | C15: 2017 | D15: 17/22 | E15: G.n[89.01]SC[160.03]AC[160.03]AGSC[160.03]K[156.13]C[160.03]K[156.13]E.C | F15: sp|P07438|MT1B_HUMAN | G15: 1560.5863 | H15: 1008 | I15: 2 | J15: 1560.5908 | K15: 781.3004 | L15: Metallothionein-1B OS=Homo sapiens GN=MT1B PE=2 SV=1 | M15: 7.62 | N15: 2268.82 | O15: 2.8798142 | P15: 51.7 | Q15: 30.8 | R15: 8.4 | S15: 9 | T15: 4.3e-06 | U15: 0.0045 | V15: 7.9746
... A319: 0.9733 | B319: MegaP_hMMP9_GluC_AP_QStar-XL_20080919.07563.07563.3 | C319: 7563 | D319: 16/96 | E319: K.n[89.01]ASGPPVSELITK[156.13]AVAASK[156.13]ERSGVSL.A | F319: sp|P16403|H12_HUMAN | G319: 2597.4097 | H319: 1386 | I319: 3 | J319: 2597.3279 | K319: 866.8105 | L319: Histone H1.2 OS=Homo sapiens GN=HIST1H1C PE=1 SV=2 | M319: 8.63 | N319: 7846.49 | O319: -31.456318 | P319: 38 | Q319: 30.1 | R319: 9.9 | S319: 8.6 | T319: 0.0062 | U319: -0.0818 | V319: 3.0649

Sheet MMP12-G
A1: Supplementary Table S2g: Human MMP12 cleavage sites identified by PICS in GluC-generated human proteome libraries | J1: back to index
A2: Peptides were identified by LC-MS/MS spectrum-to-sequence assignment with Mascot and X! Tandem, and further analysed by iProphet within TPP at a false-discovery rate of 1%. iProphet probability score, spectrum ID, peptide sequence, and scores by Mascot (ionscore, identity score, homology score) and X! Tandem (hyperscore, nextscore, bscore, yscore) are shown together with other peptide and peptide-spectrum match measures. One exemplary accession number of a matching UniProt protein entry is listed. K[156.13] denotes lysine labeled by heavy-dimethyl, C[160.03] and M[147.04] represent carbamidomethylated cysteine and oxidized methionine, respectively, and n[89.01] indicates thioacylated N-termini. Data were further processed and rendered non-redundant for generation of cleavage specificity profiles via WebPICS (http://clipserve.clip.ubc.ca/pics/) and iceLogo (http://iomics.ugent.be/icelogoserver/).
A3: ='MMP1-G'!A3 -> probability | B3: ='MMP1-G'!B3 -> spectrum | C3: ='MMP1-G'!C3 -> start scan | D3: ='MMP1-G'!D3 -> ions | E3: ='MMP1-G'!E3 -> peptide | F3: ='MMP1-G'!F3 -> protein | G3: ='MMP1-G'!G3 -> calculated neutral peptide mass | H3: ='MMP1-G'!H3 -> index | ... V3: ='MMP1-G'!V3 -> fval
A4: 0.9865 | B4: MegaP_hMMP12_GluC_CB_QStar-XL_20080812.01295.01295.4 | C4: 1295 | D4: 23/84 | E4: A.n[89.01]QK[156.13]GQK[156.13]APAQK[156.13]APAPK[156.13].A | F4: sp|P50914|RL14_HUMAN | G4: 1747.0177 | H4: 448 | I4: 4 | J4: 1746.9898 | K4: 437.7617 | L4: 60S ribosomal protein L14 OS=Homo sapiens GN=RPL14 PE=1 SV=4 | M4: 10.48 | N4: 1375.49 | O4: -15.9336 | P4: 38.4 | Q4: 28.7 | R4: 9.4 | S4: 12.5 | T4: 0.024 | U4: -0.0279 | V4: 3.4305
A5: 0.9899 | B5: MegaP_hMMP12_GluC_CB_QStar-XL_20080812.01350.01350.4 | C5: 1350 | D5: 24/102 | E5: A.n[89.01]QK[156.13]GQK[156.13]APAQK[156.13]APAPK[156.13]ASG.K | F5: sp|P50914|RL14_HUMAN | G5: 1962.1087 | H5: 451 | I5: 4 | J5: 1962.0973 | K5: 491.5345 | L5: 60S ribosomal protein L14 OS=Homo sapiens GN=RPL14 PE=1 SV=4 | M5: 10.48 | N5: 1436.39 | O5: -5.7982 | P5: 41.3 | Q5: 34.2 | R5: 10.7 | S5: 12.3 | T5: 0.004 | U5: -0.0114 | V5: 3.6132
A6: 0.9995 | B6: MegaP_hMMP12_GluC_CB_QStar-XL_20080812.01395.01395.3 | C6: 1395 | D6: 17/52 | E6: R.n[89.01]QRQPREDGNEEDK[156.13]E.N | F6: sp|P67809|YBOX1_HUMAN | G6: 1844.7957 | H6: 452 | I6: 3 | J6: 1844.7773 | K6: 615.9392 | L6: Nuclease-sensitive element-binding protein 1 OS=Homo sapiens GN=YBX1 PE=1 SV=3 | M6: 4.51 | N6: 1488.89 | O6: -9.9578 | P6: 43.5 | Q6: 32.6 | R6: 11.2 | S6: 11.3 | T6: 0.00079 | U6: -0.0184 | V6: 5.3577
A7: 1 | B7: MegaP_hMMP12_GluC_CB_QStar-XL_20080812.01532.01532.3 | C7: 1532 | D7: 25/68 | E7: H.n[89.01]QQHHQGPPPGGPGGRSEE.K | F7: sp|P23246|SFPQ_HUMAN | G7: 1938.8387 | H7: 453 | I7: 3 | J7: 1938.8171 | K7: 647.2868 | L7: Splicing factor, proline- and glutamine-rich OS=Homo sapiens GN=SFPQ PE=1 SV=2 | M7: 6.04 | N7: 1641.14 | O7: -11.1235 | P7: 63.9 | Q7: 33.9 | R7: 11.8 | S7: 12.4 | T7: 2.9e-06 | U7: -0.0216 | V7: 8.424
A8: 0.9999 | B8: MegaP_hMMP12_GluC_CB_QStar-XL_20080812.01554.01554.3 | C8: 1554 | D8: 21/68 | E8: H.n[89.01]QQHHQGPPPGGPGGRSEE.K | F8: sp|P23246|SFPQ_HUMAN,sp|P23246-2|SFPQ_HUMAN | G8: 1938.8387 | H8: 154 | I8: 3 | J8: 1938.7877 | K8: 647.2868 | L8: Splicing factor, proline- and glutamine-rich OS=Homo sapiens GN=SFPQ PE=1 SV=2 | M8: 6.04 | N8: 1671.59 | O8: -26.2642 | P8: 49.9 | Q8: 28.3 | R8: 11.9 | S8: 12 | T8: 3.9e-06 | U8: -0.051 | V8: 8.1117
A9: 0.9946 | B9: MegaP_hMMP12_GluC_CB_QStar-XL_20080812.01570.01570.3 | C9: 1570 | D9: 11/36 | E9: Y.n[89.01]NK[156.13]RSTITSRE.L | F9: sp|P33778|H2B1B_HUMAN,sp|P62807|H2B1C_HUMAN,sp|P58876|H2B1D_HUMAN,sp|Q93079|H2B1H_HUMAN,sp|P06899|H2B1J_HUMAN,sp|O60814|H2B1K_HUMAN,sp|Q99880|H2B1L_HUMAN,sp|Q99879|H2B1M_HUMAN,sp|Q99877|H2B1N_HUMAN,sp|P23527|H2B1O_HUMAN,sp|Q16778|H2B2E_HUMAN,sp|Q5QNW6|H2B2F_HUMAN,sp|Q5QNW6-2|H2B2F_HUMAN,sp|Q8N257|H2B3B_HUMAN,sp|P57053|H2BFS_HUMAN | G9: 1306.6667 | H9: 155 | I9: 3 | J9: 1306.6522 | K9: 436.5628 | L9: Histone H2B type 1-B OS=Homo sapiens GN=HIST1H2BB PE=1 SV=2 | M9: 10.84 | N9: 1691.55 | O9: -11.0715 | P9: 25.5 | Q9: 19.1 | R9: 5.7 | S9: 8.1 | T9: 0.038 | U9: -0.0145 | V9: 3.8556
A10: 0.9752 | B10: MegaP_hMMP12_GluC_CB_QStar-XL_20080812.01601.01601.2 | C10: 1601 | D10: 13/22 | E10: S.n[89.01]QTK[156.13]AGK[156.13]PEEDSE.S | F10: sp|Q13428|TCOF_HUMAN | G10: 1461.6657 | H10: 457 | I10: 2 | J10: 1461.6393 | K10: 731.8401 | L10: Treacle protein OS=Homo sapiens GN=TCOF1 PE=1 SV=3 | M10: 4.62 | N10: 1734 | O10: -18.0371 | P10: 34.4 | Q10: 25.5 | R10: 7.4 | S10: 6.5 | T10: 0.055 | U10: -0.0264 | V10: 2.9346
A11: 0.9975 | B11: MegaP_hMMP12_GluC_CB_QStar-XL_20080812.01629.01629.3 | C11: 1629 | D11: 17/60 | E11: N.n[89.01]QGK[156.13]K[156.13]VDTTPNQGK[156.13]K[156.13]VE.G | F11: sp|Q9P2E9|RRBP1_HUMAN,sp|Q9P2E9-2|RRBP1_HUMAN | G11: 1956.0717 | H11: 35 | I11: 3 | J11: 1956.0418 | K11: 653.0312 | L11: Ribosome-binding protein 1 OS=Homo sapiens GN=RRBP1 PE=1 SV=4 | M11: 9.53 | N11: 1774.65 | O11: -15.2624 | P11: 37.9 | Q11: 26.4 | R11: 11.3 | S11: 11 | T11: 0.00041 | U11: -0.0299 | V11: 5.6168
A12: 0.9938 | B12: MegaP_hMMP12_GluC_CB_QStar-XL_20080812.01648.01648.2 | C12: 1648 | D12: 10/20 | E12: E.n[29.04]C[160.03]C[160.03]AK[156.13]DDPHAC[160.03]Y.S | F12: CON_P02769|P02769 | G12: 1451.5627 | H12: 159 | I12: 2 | J12: 1451.5436 | K12: 726.7886 | L12: (Bos taurus) Bovine serum albumin precursor | M12: 5.21 | N12: 1811.65 | O12: -13.1402 | P12: 31.2 | Q12: 21.8 | R12: 13.5 | S12: 12.5 | T12: 0.017 | U12: -0.0191 | V12: 3.8191
A13: 0.9588 | B13: MegaP_hMMP12_GluC_CB_QStar-XL_20080812.01662.01662.2 | C13: 1662 | D13: 12/18 | E13: T.n[89.01]QK[156.13]TVDGPSGK[156.13].L | F13: sp|P04406|G3P_HUMAN | G13: 1159.5907 | H13: 732 | I13: 2 | J13: 1159.5721 | K13: 580.8026 | L13: Glyceraldehyde-3-phosphate dehydrogenase OS=Homo sapiens GN=GAPDH PE=1 SV=3 | M13: 8.59 | N13: 1840.2 | O13: -16.0126 | P13: 35.1 | Q13: 27.3 | R13: 9.8 | S13: 11.3 | T13: 0.094 | U13: -0.0186 | V13: 2.7207
A14: 0.9995 | B14: MegaP_hMMP12_GluC_CB_QStar-XL_20080812.01664.01664.3 | C14: 1664 | D14: 20/48 | E14: N.n[89.01]VTATDK[156.13]STGK[156.13]ANK[156.13].L | F14: sp|P08107|HSP71_HUMAN | G14: 1491.7967 | H14: 458 | I14: 3 | J14: 1491.7506 | K14: 498.2728 | L14: Heat shock 70 kDa protein 1A\1B OS=Homo sapiens GN=HSPA1A PE=1 SV=5 | M14: 9.7 | N14: 1841.25 | O14: -30.8408 | P14: 48.3 | Q14: 48.3 | R14: 9.9 | S14: 11.7 | T14: 9.9e-05 | U14: -0.0461 | V14: 5.3146
A15: 0.9864 | B15: MegaP_hMMP12_GluC_CB_QStar-XL_20080812.01676.01676.3 | C15: 1676 | D15: 15/44 | E15: P.n[89.01]HK[156.13]VDGRVVEPK[156.13]R.A | F15: sp|Q32P51|RA1L2_HUMAN | G15: 1562.8717 | H15: 460 | I15: 3 | J15: 1562.827 | K15: 521.9645 | L15: Heterogeneous nuclear ribonucleoprotein A1-like 2 OS=Homo sapiens GN=HNRNPA1L2 PE=2 SV=2 | M15: 9.99 | N15: 1863.45 | O15: -28.5468 | P15: 33 | Q15: 25.3 | R15: 11.7 | S15: 11.8 | T15: 0.078 | U15: -0.0447 | V15: 3.02
... A17: 0.9821 | B17: MegaP_hMMP12_GluC_CB_QStar-XL_20080812.01691.01691.2 | C17: 1691 | D17: 9/16 | E17: D.n[89.01]SRSAGVPSR.V | F17: sp|P26599|PTBP1_HUMAN,sp|P26599-2|PTBP1_HUMAN,sp|P26599-3|PTBP1_HUMAN | G17: 1003.4867 | H17: 110 | I17: 2 | J17: 1003.4627 | K17: 502.7506 | L17: Polypyrimidine tract-binding protein 1 OS=Homo sapiens GN=PTBP1 PE=1 SV=1 | M17: 12 | N17: 1890.95 | O17: -23.8693 | P17: 26.7 | Q17: 22.9 | R17: 11.6 | S17: 11.6 | T17: 0.096 | U17: -0.024 | V17: 2.4089
A18: 0.9871 | B18: MegaP_hMMP12_GluC_CB_QStar-XL_20080812.01700.01700.2 | C18: 1700 | D18: 14/20 | E18: H.n[89.01]VDSGK[156.13]STTTGH.L | F18: sp|P68104|EF1A1_HUMAN | G18: 1204.5397 | H18: 467 | I18: 2 | J18: 1204.5052 | K18: 603.2771 | L18: Elongation factor 1-alpha 1 OS=Homo sapiens GN=EEF1A1 PE=1 SV=1 | M18: 6.71 | N18: 1905.75 | O18: =(((IF(U4<0.51,U4, IF(U4<1.51,U4-1.003355,IF(U4<2.6,U4-2*1.003355))))/I4)/K4)*1000000 -> -15.933326 | P18: 40.1 | Q18: 29.5 | R18: 8.5 | S18: 9.9 | T18: 0.027 | U18: -0.0345 | V18: 3.4177
A19: 0.9981 | B19: MegaP_hMMP12_GluC_CB_QStar-XL_20080812.01703.01703.2 | C19: 1703 | D19: 16/20 | E19: A.n[89.01]QTAPNK[156.13]DVQRE.L | F19: sp|P49588|SYAC_HUMAN | G19: 1400.6717 | H19: 161 | I19: 2 | J19: 1400.6505 | K19: 701.3431 | L19: Alanine--tRNA ligase, cytoplasmic OS=Homo sapiens GN=AARS PE=1 SV=2 | M19: 6.25 | N19: 1913.15 | O19: =(((IF(U5<0.51,U5, IF(U5<1.51,U5-1.003355,IF(U5<2.6,U5-2*1.003355))))/I5)/K5)*1000000 -> -5.7981688 | P19: 51.1 | Q19: 36.2 | R19: 10.3 | S19: 11.8 | T19: 0.00056 | U19: -0.0212 | V19: 5.4188
A20: 0.9904 | B20: MegaP_hMMP12_GluC_CB_QStar-XL_20080812.01705.01705.3 | C20: 1705 | D20: 18/48 | E20: N.n[89.01]VTATDK[156.13]STGK[156.13]ANK[156.13].L | F20: sp|P08107|HSP71_HUMAN | G20: 1491.7967 | H20: 468 | I20: 3 | J20: 1491.7653 | K20: 498.2728 | L20: Heat shock 70 kDa protein 1A\1B OS=Homo sapiens GN=HSPA1A PE=1 SV=5 | M20: 9.7 | N20: 1913.15 | O20: =(((IF(U6<0.51,U6, IF(U6<1.51,U6-1.003355,IF(U6<2.6,U6-2*1.003355))))/I6)/K6)*1000000 -> -9.9576928 | P20: 40.4 | Q20: 40.4 | R20: 8.9 | S20: 10.4 | T20: 0.0042 | U20: -0.0314 | V20: 3.2357
A21: 0.9913 | B21: MegaP_hMMP12_GluC_CB_QStar-XL_20080812.01748.01748.3 | C21: 1748 | D21: 14/40 | E21: E.n[89.01]DRVRGPK[156.13]GPEE.K | F21: sp|Q00839|HNRPU_HUMAN,sp|Q00839-2|HNRPU_HUMAN | G21: 1354.6667 | H21: 37 | I21: 3 | J21: 1354.6397 | K21: 452.5628 | L21: Heterogeneous nuclear ribonucleoprotein U OS=Homo sapiens GN=HNRNPU PE=1 SV=6 | M21: 6.3 | N21: 1994.55 | O21: =(((IF(U7<0.51,U7, IF(U7<1.51,U7-1.003355,IF(U7<2.6,U7-2*1.003355))))/I7)/K7)*1000000 -> -11.123354 | P21: 32.2 | Q21: 24.5 | R21: 9.5 | S21: 9.3 | T21: 0.013 | U21: -0.027 | V21: 4.2608
A22: 0.9741 | B22: MegaP_hMMP12_GluC_CB_QStar-XL_20080812.01768.01768.2 | C22: 1768 | D22: 17/18 | E22: N.n[89.01]VTATDK[156.13]STGK[156.13].A | F22: sp|P08107|HSP71_HUMAN | G22: 1150.5907 | H22: 473 | I22: 2 | J22: 1150.5641 | K22: 576.3026 | L22: Heat shock 70 kDa protein 1A\1B OS=Homo sapiens GN=HSPA1A PE=1 SV=5 | M22: 8.56 | N22: 2031.55 | O22: =(((IF(U8<0.51,U8, IF(U8<1.51,U8-1.003355,IF(U8<2.6,U8-2*1.003355))))/I8)/K8)*1000000 -> -26.263474 | P22: 54.1 | Q22: 54.1 | R22: 8 | S22: 10.8 | T22: 0.0071 | U22: -0.0266 | V22: 2.9033
A23: 0.9992 | B23: MegaP_hMMP12_GluC_CB_QStar-XL_20080812.01775.01775.3 | C23: 1775 | D23: 18/80 | E23: K.n[29.04]APK[156.13]PDGPGGGPGGSHMGGNYG.D | F23: sp|P35637|FUS_HUMAN | G23: 1921.8737 | H23: 840 | I23: 3 | J23: 1921.8248 | K23: 641.6318 | L23: RNA-binding protein FUS OS=Homo sapiens GN=FUS PE=1 SV=1 | M23: 6.79 | N23: 2048.5 | O23: =(((IF(U9<0.51,U9, IF(U9<1.51,U9-1.003355,IF(U9<2.6,U9-2*1.003355))))/I9)/K9)*1000000 -> -11.071336 | P23: 41.1 | Q23: 27.5 | R23: 10.6 | S23: 9.3 | T23: 4.5e-05 | U23: -0.0489 | V23: 6.0124
A24: 0.9979 | B24: MegaP_hMMP12_GluC_CB_QStar-XL_20080812.01787.01787.3 | C24: 1787 | D24: 15/36 | E24: A.n[89.01]LK[156.13]PK[156.13]VPK[156.13]K[156.13]EE.S | F24: sp|P46821|MAP1B_HUMAN | G24: 1394.8567 | H24: 168 | I24: 3 | J24: 1394.8138 | K24: 465.9595 | L24: Microtubule-associated protein 1B OS=Homo sapiens GN=MAP1B PE=1 SV=2 | M24: 9.53 | N24: 2068.55 | O24: =(((IF(U10<0.51,U10, IF(U10<1.51,U10-1.003355,IF(U10<2.6,U10-2*1.003355))))/I10)/K10)*1000000 -> -18.036727 | P24: 32.6 | Q24: 20.8 | R24: 10.3 | S24: 11.9 | T24: 0.025 | U24: -0.0429 | V24: 4.8223
A25: 0.9941 | B25: MegaP_hMMP12_GluC_CB_QStar-XL_20080812.01803.01803.3 | C25: 1803 | D25: 14/40 | E25: H.n[89.01]YNK[156.13]RSTITSRE.L | F25: sp|P33778|H2B1B_HUMAN,sp|P62807|H2B1C_HUMAN,sp|P58876|H2B1D_HUMAN,sp|Q93079|H2B1H_HUMAN,sp|P06899|H2B1J_HUMAN,sp|O60814|H2B1K_HUMAN,sp|Q99880|H2B1L_HUMAN,sp|Q99879|H2B1M_HUMAN,sp|Q99877|H2B1N_HUMAN,sp|P23527|H2B1O_HUMAN,sp|Q16778|H2B2E_HUMAN,sp|Q5QNW6|H2B2F_HUMAN,sp|Q5QNW6-2|H2B2F_HUMAN,sp|Q8N257|H2B3B_HUMAN,sp|P57053|H2BFS_HUMAN | G25: 1469.7297 | H25: 170 | I25: 3 | J25: 1469.696 | K25: 490.9172 | L25: Histone H2B type 1-B OS=Homo sapiens GN=HIST1H2BB PE=1 SV=2 | M25: 9.99 | N25: 2098.15 | O25: =(((IF(U11<0.51,U11, IF(U11<1.51,U11-1.003355,IF(U11<2.6,U11-2*1.003355))))/I11)/K11)*1000000 -> -15.26216 | P25: 27.5 | Q25: 21.8 | R25: 7.1 | S25: 7.3 | T25: 0.023 | U25: -0.0337 | V25: 3.7247
A26: 0.9997 | B26: MegaP_hMMP12_GluC_CB_QStar-XL_20080812.01817.01817.2 | C26: 1817 | D26: 14/26 | E26: E.n[29.04]HGIDPTGTYHGDSD.L | F26: sp|P04350|TBB4A_HUMAN | G26: 1498.6327 | H26: 737 | I26: 2 | J26: 1498.5987 | K26: 750.3236 | L26: Tubulin beta-4A chain OS=Homo sapiens GN=TUBB4A PE=1 SV=2 | M26: 4.63 | N26: 2126.7 | O26: =(((IF(U12<0.51,U12, IF(U12<1.51,U12-1.003355,IF(U12<2.6,U12-2*1.003355))))/I12)/K12)*1000000 -> -13.139997 | P26: 41.4 | Q26: 21.1 | R26: 11.1 | S26: 9 | T26: 1.1e-06 | U26: -0.034 | V26: 8.3638
A27: 0.9955 | B27: MegaP_hMMP12_GluC_CB_QStar-XL_20080812.01821.01821.2 | C27: 1821 | D27: 12/18 | E27: Q.n[89.01]VVQK[156.13]K[156.13]PAQEE.T | F27: sp|P52926|HMGA2_HUMAN | G27: 1298.6907 | H27: 373 | I27: 2 | J27: 1298.6538 | K27: 650.3526 | L27: High mobility group protein HMGI-C OS=Homo sapiens GN=HMGA2 PE=1 SV=1 | M27: 6.25 | N27: 2134.11 | O27: =(((IF(U13<0.51,U13, IF(U13<1.51,U13-1.003355,IF(U13<2.6,U13-2*1.003355))))/I13)/K13)*1000000 -> -16.012325 | P27: 35.7 | Q27: 27 | R27: 10.4 | S27: 10.7 | T27: 0.0038 | U27: -0.0369 | V27: 4.4526
A28: 0.9986 | B28: MegaP_hMMP12_GluC_CB_QStar-XL_20080812.01824.01824.2 | C28: 1824 | D28: 14/40 | E28: R.n[89.01]LK[156.13]TDNAGDQHGGGGGGGGGAG.A | F28: sp|P14866|HNRPL_HUMAN | G28: 1854.7917 | H28: 738 | I28: 2 | J28: 1854.7392 | K28: 928.4031 | L28: Heterogeneous nuclear ribonucleoprotein L OS=Homo sapiens GN=HNRNPL PE=1 SV=2 | M28: 5.21 | N28: 2139.41 | O28: =(((IF(U14<0.51,U14, IF(U14<1.51,U14-1.003355,IF(U14<2.6,U14-2*1.003355))))/I14)/K14)*1000000 -> -30.839867 | P28: 42 | Q28: 27.6 | R28: 12.2 | S28: 8.6 | T28: 1.4e-05 | U28: -0.0525 | V28: 5.4993
A29: 0.9914 | B29: MegaP_hMMP12_GluC_CB_QStar-XL_20080812.01840.01840.3 | C29: 1840 | D29: 15/36 | E29: Q.n[89.01]LK[156.13]RQPAPPRE.A | F29: sp|P46778|RL21_HUMAN | G29: 1306.7177 | H29: 171 | I29: 3 | J29: 1306.6825 | K29: 436.5798 | L29: 60S ribosomal protein L21 OS=Homo sapiens GN=RPL21 PE=1 SV=2 | M29: 10.84 | N29: 2164.76 | O29: =(((IF(U15<0.51,U15, IF(U15<1.51,U15-1.003355,IF(U15<2.6,U15-2*1.003355))))/I15)/K15)*1000000 -> -28.546003 | P29: 33.8 | Q29: 28.5 | R29: 11.1 | S29: 11.5 | T29: 0.027 | U29: -0.0352 | V29: 3.4761
... A257: 0.9987 | B257: MegaP_hMMP12_GluC_CB_QStar-XL_20080812.07359.07359.2 | C257: 7359 | D257: 13/24 | E257: N.n[89.01]LK[156.13]VAGQDGSVVQF.K | F257: sp|P61956|SUMO2_HUMAN | G257: 1462.7487 | H257: 697 | I257: 2 | J257: 1462.7285 | K257: 732.3816 | L257: Small ubiquitin-related modifier 2 OS=Homo sapiens GN=SUMO2 PE=1 SV=3 | M257: 5.84 | N257: 6716.48 | O257: =(((IF(U243<0.51,U243, IF(U243<1.51,U243-1.003355,IF(U243<2.6,U243-2*1.003355))))/I243)/K243)*1000000 -> -25.974327 | P257: 40.6 | Q257: 27.8 | R257: 10.8 | S257: 8.7 | T257: 0.00024 | U257: -0.0202 | V257: 5.4977

Sheet MMP13-G
A1: Supplementary Table S2h: Human MMP13 cleavage sites identified by PICS in GluC-generated human proteome libraries | J1: back to index
