Workbook

Sheet Supplementary Table 1
K1: Eckhard et al. 2015
A4: Supplementary Table 1: Human MMP cleavage sites identified by PICS in trypsin-generated human proteome libraries
A6: Human MMP | B6: MMP1 | C6: MMP2 | D6: MMP3 | E6: MMP7 | F6: MMP8 | G6: MMP9 | H6: MMP12 | I6: MMP13 | J6: MMP14 | K6: Total
A7: Number of cleavage sites | B7: 305 | C7: 699 | D7: 208 | E7: 311 | F7: 352 | G7: 161 | H7: 289 | I7: 155 | J7: 342 | K7: 2822
A8: Unique P6-to-P6' cleavage sites | B8: 270 | C8: 612 | D8: 185 | E8: 278 | F8: 320 | G8: 134 | H8: 259 | I8: 136 | J8: 293 | K8: 2487

Sheet MMP1-T
A1: Supplementary Table 1a: Human MMP1 cleavage sites identified by PICS in trypsin-generated human proteome libraries | J1: back to index
A2: Peptides were identified by LC-MS/MS spectrum-to-sequence assignment with Mascot and X! Tandem, and further analysed by iProphet within TPP at a false-discovery rate of 1%. iProphet probability score, spectrum ID, peptide sequence, and scores by Mascot (ionscore, identity score, homology score) and X! Tandem (hyperscore, nextscore, bscore, yscore) are shown together with other peptide and peptide-spectrum match measures. One exemplary accession number of a matching UniProt protein entry is listed. K[156.13] denotes lysine labeled by heavy-dimethyl, C[160.03] and M[147.04] represent carbamidomethylated cysteine and oxidized methionine, respectively, and n[89.01] indicates thioacylated N-termini. Data were further processed and rendered non-redundant for generation of cleavage specificity profiles via WebPICS (http://clipserve.clip.ubc.ca/pics/) and iceLogo (http://iomics.ugent.be/icelogoserver/).
A3: probability | B3: spectrum | C3: start scan | D3: ions | E3: peptide | F3: protein | G3: calculated neutral peptide mass | H3: index | I3: assumed charge | J3: precursor neutral mass | K3: m/z ratio | L3: protein description | M3: pI | N3: retention time (sec) | O3: ppm | P3: hyperscore | Q3: nextscore | R3: bscore | S3: yscore | T3: expect | U3: mass diff | V3: fval
A4: 0.9999 | B4: MegaP_hMMP1_Tryps_GB_QStar-XL_20110215.02392.02392.3 | C4: 2392 | D4: 12/32 | E4: K.n[29.04]YMEHEERPK[156.13].A | F4: sp|O95757|HS74L_HUMAN | G4: 1273.6127 | H4: 1716 | I4: 3 | J4: 1273.5783 | K4: 425.5448 | L4: Heat shock 70 kDa protein 4L OS=Homo sapiens GN=HSPA4L PE=1 SV=3 | M4: 5.5 | N4: 2631 | O4: -26.945851 | P4: 30 | Q4: 20.8 | R4: 3.5 | S4: 10.2 | T4: 0.0049 | U4: -0.0344 | V4: 5.7901
A5: 0.9799 | B5: MegaP_hMMP1_Tryps_GB_QStar-XL_20110215.02395.02395.3 | C5: 2395 | D5: 10/32 | E5: K.n[29.04]YMEHEERPK[156.13].A | F5: sp|O95757|HS74L_HUMAN | G5: 1273.6127 | H5: 385 | I5: 3 | J5: 1274.5833 | K5: 425.5448 | L5: Heat shock 70 kDa protein 4L OS=Homo sapiens GN=HSPA4L PE=1 SV=3 | M5: 5.5 | N5: 2635.2 | O5: -25.657306 | P5: 24 | Q5: 19 | R5: 2.7 | S5: 9.4 | T5: 0.25 | U5: 0.9706 | V5: 2.5131
A6: 0.9969 | B6: MegaP_hMMP1_Tryps_GB_QStar-XL_20110215.02406.02406.4 | C6: 2406 | D6: 13/78 | E6: K.n[29.04]APGTPHSHTK[156.13]PYVR.S | F6: sp|Q07020|RL18_HUMAN | G6: 1602.8627 | H6: 1211 | I6: 4 | J6: 1603.8468 | K6: 401.723 | L6: 60S ribosomal protein L18 OS=Homo sapiens GN=RPL18 PE=1 SV=2 | M6: 10 | N6: 2648.85 | O6: -11.982759 | P6: 31.3 | Q6: 23.3 | R6: 10.9 | S6: 12.6 | T6: 0.012 | U6: 0.9841 | V6: 3.9303
A7: 1 | B7: MegaP_hMMP1_Tryps_GB_QStar-XL_20110215.02410.02410.3 | C7: 2410 | D7: 16/44 | E7: R.n[29.04]YINTEHGGSQAR.F | F7: sp|Q15437|SC23B_HUMAN | G7: 1359.6527 | H7: 1568 | I7: 3 | J7: 1359.6234 | K7: 454.2248 | L7: Protein transport protein Sec23B OS=Homo sapiens GN=SEC23B PE=1 SV=2 | M7: 6.75 | N7: 2655.15 | O7: -21.501835 | P7: 36.2 | Q7: 21.2 | R7: 7.2 | S7: 9.4 | T7: 4.4e-05 | U7: -0.0293 | V7: 8.3839
A8: 1 | B8: MegaP_hMMP1_Tryps_GB_QStar-XL_20110215.02423.02423.3 | C8: 2423 | D8: 14/44 | E8: K.n[29.04]YHTVNGHNC[160.03]EVR.K | F8: sp|P09651|ROA1_HUMAN | G8: 1512.6887 | H8: 2480 | I8: 3 | J8: 1512.6493 | K8: 505.2368 | L8: Heterogeneous nuclear ribonucleoprotein A1 OS=Homo sapiens GN=HNRNPA1 PE=1 SV=5 | M8: 6.91 | N8: 2678.19 | O8: -25.994412 | P8: 36.5 | Q8: 24.7 | R8: 6 | S8: 8.4 | T8: 6e-05 | U8: -0.0394 | V8: 7.679
A9: 1 | B9: MegaP_hMMP1_Tryps_GB_QStar-XL_20110215.02426.02426.3 | C9: 2426 | D9: 13/44 | E9: K.n[29.04]YHTVNGHNC[160.03]EVR.K | F9: sp|P09651|ROA1_HUMAN,sp|P09651-2|ROA1_HUMAN,sp|P09651-3|ROA1_HUMAN | G9: 1512.6887 | H9: 1938 | I9: 3 | J9: 1513.6623 | K9: 505.2368 | L9: Heterogeneous nuclear ribonucleoprotein A1 OS=Homo sapiens GN=HNRNPA1 PE=1 SV=5 | M9: 6.91 | N9: 2683.4 | O9: -19.631059 | P9: 34.7 | Q9: 19.3 | R9: 6.7 | S9: 7.7 | T9: 1.4e-05 | U9: 0.9736 | V9: 9.215
A10: 0.9998 | B10: MegaP_hMMP1_Tryps_GB_QStar-XL_20110215.02427.02427.3 | C10: 2427 | D10: 12/44 | E10: K.n[29.04]YHTVNGHNC[160.03]EVR.K | F10: sp|P09651|ROA1_HUMAN,sp|P09651-2|ROA1_HUMAN,sp|P09651-3|ROA1_HUMAN | G10: 1512.6887 | H10: 1195 | I10: 3 | J10: 1514.6463 | K10: 505.2368 | L10: Heterogeneous nuclear ribonucleoprotein A1 OS=Homo sapiens GN=HNRNPA1 PE=1 SV=5 | M10: 6.91 | N10: 2685.45 | O10: -32.400649 | P10: 29.9 | Q10: 21.4 | R10: 6.8 | S10: 7.5 | T10: 0.00044 | U10: 1.9576 | V10: 6.3035
A11: 0.9986 | B11: MegaP_hMMP1_Tryps_GB_QStar-XL_20110215.02440.02440.3 | C11: 2440 | D11: 14/36 | E11: K.n[29.04]YTQVGPDHNR.S | F11: sp|Q08211|DHX9_HUMAN | G11: 1213.5837 | H11: 1984 | I11: 3 | J11: 1213.5707 | K11: 405.5352 | L11: ATP-dependent RNA helicase A OS=Homo sapiens GN=DHX9 PE=1 SV=4 | M11: 6.74 | N11: 2711.55 | O11: -10.685468 | P11: 30.7 | Q11: 26.2 | R11: 7.2 | S11: 9.2 | T11: 0.011 | U11: -0.013 | V11: 3.9793
A12: 0.9757 | B12: MegaP_hMMP1_Tryps_GB_QStar-XL_20110215.02443.02443.3 | C12: 2443 | D12: 13/36 | E12: K.n[29.04]YTQVGPDHNR.S | F12: sp|Q08211|DHX9_HUMAN | G12: 1213.5837 | H12: 1844 | I12: 3 | J12: 1214.5647 | K12: 405.5352 | L12: ATP-dependent RNA helicase A OS=Homo sapiens GN=DHX9 PE=1 SV=4 | M12: 6.74 | N12: 2716.75 | O12: -18.374895 | P12: 28.5 | Q12: 25.2 | R12: 7.8 | S12: 9.5 | T12: 0.066 | U12: 0.981 | V12: 2.6514
A13: 0.9999 | B13: MegaP_hMMP1_Tryps_GB_QStar-XL_20110215.02444.02444.3 | C13: 2444 | D13: 10/32 | E13: K.n[29.04]YMEHEERPK[156.13].A | F13: sp|O95757|HS74L_HUMAN | G13: 1273.6127 | H13: 1 | I13: 3 | J13: 1273.5783 | K13: 425.5448 | L13: Heat shock 70 kDa protein 4L OS=Homo sapiens GN=HSPA4L PE=1 SV=3 | M13: 5.5 | N13: 2628.9 | O13: -26.945851 | P13: 26.8 | Q13: 18.7 | R13: 0 | S13: 10.1 | T13: 0.021 | U13: -0.0344 | V13: 4.7904
A14: 0.9995 | B14: MegaP_hMMP1_Tryps_GB_QStar-XL_20110215.02447.02447.3 | C14: 2447 | D14: 11/32 | E14: K.n[29.04]YMEHEERPK[156.13].A | F14: sp|O95757|HS74L_HUMAN | G14: 1273.6127 | H14: 644 | I14: 3 | J14: 1274.5833 | K14: 425.5448 | L14: Heat shock 70 kDa protein 4L OS=Homo sapiens GN=HSPA4L PE=1 SV=3 | M14: 5.5 | N14: 2633.1 | O14: -25.657306 | P14: 26.4 | Q14: 17.3 | R14: 1.4 | S14: 9.4 | T14: 0.029 | U14: 0.9706 | V14: 4.8583
A15: 1 | B15: MegaP_hMMP1_Tryps_GB_QStar-XL_20110215.02456.02456.4 | C15: 2456 | D15: 13/78 | E15: K.n[29.04]APGTPHSHTK[156.13]PYVR.S | F15: sp|Q07020|RL18_HUMAN | G15: 1602.8627 | H15: 645 | I15: 4 | J15: 1602.8336 | K15: 401.723 | L15: 60S ribosomal protein L18 OS=Homo sapiens GN=RPL18 PE=1 SV=2 | M15: 10 | N15: 2643.6 | O15: -18.109493 | P15: 33.2 | Q15: 22.4 | R15: 0 | S15: 12.9 | T15: 0.0049 | U15: -0.0291 | V15: 4.7817
... A1354: 0.9993 | B1354: MegaP_hMMP1_Tryps_GB_QStar-XL_20110215.06204.06204.2 | C1354: 6204 | D1354: 14/24 | E1354: N.n[89.01]IVGLVGVDQFLVK[156.13].T | F1354: sp|P13639|EF2_HUMAN | G1354: 1501.8577 | H1354: 2278 | I1354: 2 | J1354: 1502.8348 | K1354: 751.9361 | L1354: Elongation factor 2 OS=Homo sapiens GN=EEF2 PE=1 SV=4 | M1354: 5.84 | N1354: 9102.76 | O1354: -17.458265 | P1354: 43.4 | Q1354: 26 | R1354: 10.9 | S1354: 9.9 | T1354: 7.3e-05 | U1354: 0.9771 | V1354: 6.406

Sheet MMP2-T
A1: Supplementary Table 1b: Human MMP2 cleavage sites identified by PICS in trypsin-generated human proteome libraries | J1: back to index
A2: Peptides were identified by LC-MS/MS spectrum-to-sequence assignment with Mascot and X! Tandem, and further analysed by iProphet within TPP at a false-discovery rate of 1%. iProphet probability score, spectrum ID, peptide sequence, and scores by Mascot (ionscore, identity score, homology score) and X! Tandem (hyperscore, nextscore, bscore, yscore) are shown together with other peptide and peptide-spectrum match measures. One exemplary accession number of a matching UniProt protein entry is listed. K[156.13] denotes lysine labeled by heavy-dimethyl, C[160.03] and M[147.04] represent carbamidomethylated cysteine and oxidized methionine, respectively, and n[89.01] indicates thioacylated N-termini. Data were further processed and rendered non-redundant for generation of cleavage specificity profiles via WebPICS (http://clipserve.clip.ubc.ca/pics/) and iceLogo (http://iomics.ugent.be/icelogoserver/).
A3: ='MMP1-T'!A3 -> probability | B3: ='MMP1-T'!B3 -> spectrum | C3: ='MMP1-T'!C3 -> start scan | D3: ='MMP1-T'!D3 -> ions | E3: ='MMP1-T'!E3 -> peptide | F3: ='MMP1-T'!F3 -> protein | G3: ='MMP1-T'!G3 -> calculated neutral peptide mass | H3: ='MMP1-T'!H3 -> index | ... V3: ='MMP1-T'!V3 -> fval
A4: 0.9999 | B4: MegaP_hMMP2_Tryps-1_OS_QStar-XL_20111027.01631.01631.4 | C4: 1631 | D4: 18/138 | E4: K.n[29.04]APK[156.13]PDGPGGGPGGSHM[147.04]GGNYGDDR.R | F4: sp|P35637|FUS_HUMAN,sp|P35637-2|FUS_HUMAN | G4: 2324.0237 | H4: 913 | I4: 4 | J4: 2324.1957 | K4: 582.0132 | L4: RNA-binding protein FUS OS=Homo sapiens GN=FUS PE=1 SV=1 | M4: 5.3 | N4: 1722.06 | O4: 73.881486 | P4: 36.7 | Q4: 22.2 | R4: 8.8 | S4: 11.7 | T4: 4.5e-05 | U4: 0.172 | V4: 5.8991
A5: 0.9285 | B5: MegaP_hMMP2_Tryps-1_OS_QStar-XL_20111027.01668.01668.2 | C5: 1668 | D5: 3/14 | E5: Q.n[29.04]K[156.13]K[156.13]LK[156.13]LLQK[156.13].K | F5: sp|Q8N3L3|TXLNB_HUMAN | G5: 1137.8577 | H5: 2473 | I5: 2 | J5: 1139.0888 | K5: 569.9361 | L5: Beta-taxilin OS=Homo sapiens GN=TXLNB PE=1 SV=3 | M5: 10.48 | N5: 1777.31 | O5: 199.79871 | P5: 11.9 | Q5: 11.1 | R5: 0 | S5: 8.8 | T5: 0.0069 | U5: 1.2311 | V5: 3.5953
A6: 0.9999 | B6: MegaP_hMMP2_Tryps-1_OS_QStar-XL_20111027.01728.01728.4 | C6: 1728 | D6: 19/84 | E6: K.n[29.04]GVTEC[160.03]YEC[160.03]HPK[156.13]PTQR.T | F6: sp|Q9UBT2|SAE2_HUMAN | G6: 1916.8877 | H6: 76 | I6: 4 | J6: 1917.1107 | K6: 480.2292 | L6: SUMO-activating enzyme subunit 2 OS=Homo sapiens GN=UBA2 PE=1 SV=2 | M6: 6.74 | N6: 1886.71 | O6: 116.0904 | P6: 41.5 | Q6: 28.8 | R6: 10.4 | S6: 11.9 | T6: 0.0011 | U6: 0.223 | V6: 5.2982
A7: 0.9959 | B7: MegaP_hMMP2_Tryps-1_OS_QStar-XL_20111027.01775.01775.4 | C7: 1775 | D7: 16/138 | E7: K.n[29.04]APK[156.13]PDGPGGGPGGSHMGGNYGDDR.R | F7: sp|P35637|FUS_HUMAN,sp|P35637-2|FUS_HUMAN | G7: 2308.0287 | H7: 915 | I7: 4 | J7: 2308.1607 | K7: 578.0145 | L7: RNA-binding protein FUS OS=Homo sapiens GN=FUS PE=1 SV=1 | M7: 5.3 | N7: 2000.56 | O7: 57.091993 | P7: 32.9 | Q7: 23.2 | R7: 10 | S7: 11.4 | T7: 0.0051 | U7: 0.132 | V7: 3.5586
A8: 0.927 | B8: MegaP_hMMP2_Tryps-1_OS_QStar-XL_20111027.01778.01778.4 | C8: 1778 | D8: 14/138 | E8: K.n[29.04]APK[156.13]PDGPGGGPGGSHMGGNYGDDR.R | F8: sp|P35637|FUS_HUMAN,sp|P35637-2|FUS_HUMAN | G8: 2308.0287 | H8: 523 | I8: 4 | J8: 2309.7176 | K8: 578.0145 | L8: RNA-binding protein FUS OS=Homo sapiens GN=FUS PE=1 SV=1 | M8: 5.3 | N8: 2011.01 | O8: -137.45762 | P8: 32.2 | Q8: 26.8 | R8: 9.3 | S8: 11.7 | T8: 0.0096 | U8: 1.6889 | V8: 2.7814
A9: 1 | B9: MegaP_hMMP2_Tryps-1_OS_QStar-XL_20111027.01790.01790.4 | C9: 1790 | D9: 19/138 | E9: K.n[29.04]APK[156.13]PDGPGGGPGGSHMGGNYGDDR.R | F9: sp|P35637|FUS_HUMAN,sp|P35637-2|FUS_HUMAN | G9: 2308.0287 | H9: 916 | I9: 4 | J9: 2308.1777 | K9: 578.0145 | L9: RNA-binding protein FUS OS=Homo sapiens GN=FUS PE=1 SV=1 | M9: 5.3 | N9: 2037.06 | O9: 64.44475 | P9: 40.7 | Q9: 23.5 | R9: 9.2 | S9: 12.1 | T9: 1.2e-05 | U9: 0.149 | V9: 6.551
A10: 0.9999 | B10: MegaP_hMMP2_Tryps-1_OS_QStar-XL_20111027.01806.01806.4 | C10: 1806 | D10: 18/90 | E10: R.n[29.04]YFDGSGGNNHAVEHYR.E | F10: sp|P45974|UBP5_HUMAN,sp|P45974-2|UBP5_HUMAN | G10: 1849.8127 | H10: 917 | I10: 4 | J10: 1849.9629 | K10: 463.4605 | L10: Ubiquitin carboxyl-terminal hydrolase 5 OS=Homo sapiens GN=USP5 PE=1 SV=2 | M10: 5.99 | N10: 2073.56 | O10: 81.020928 | P10: 32.1 | Q10: 19.8 | R10: 4.5 | S10: 7.8 | T10: 0.0005 | U10: 0.1502 | V10: 5.9163
A11: 0.9528 | B11: MegaP_hMMP2_Tryps-1_OS_QStar-XL_20111027.01808.01808.3 | C11: 1808 | D11: 13/44 | E11: R.n[29.04]AINEAYK[156.13]EDYHK[156.13].S | F11: sp|P08133|ANXA6_HUMAN,sp|P08133-2|ANXA6_HUMAN | G11: 1563.7937 | H11: 1525 | I11: 3 | J11: 1563.8705 | K11: 522.2718 | L11: Annexin A6 OS=Homo sapiens GN=ANXA6 PE=1 SV=3 | M11: 5.45 | N11: 2084.01 | O11: 49.016623 | P11: 28.3 | Q11: 25.4 | R11: 9.6 | S11: 11.6 | T11: 0.028 | U11: 0.0768 | V11: 2.856
A12: 0.9952 | B12: MegaP_hMMP2_Tryps-1_OS_QStar-XL_20111027.01841.01841.2 | C12: 1841 | D12: 7/20 | E12: P.n[29.04]VLPSVLK[156.13]LPVR.S | F12: sp|Q9NZE8|RM35_HUMAN | G12: 1275.8647 | H12: 1850 | I12: 2 | J12: 1276.0779 | K12: 638.9396 | L12: 39S ribosomal protein L35, mitochondrial OS=Homo sapiens GN=MRPL35 PE=1 SV=3 | M12: 11 | N12: 2161.16 | O12: 166.83893 | P12: 23 | Q12: 14.2 | R12: 0 | S12: 8.2 | T12: 0.015 | U12: 0.2132 | V12: 4.2718
A13: 1 | B13: MegaP_hMMP2_Tryps-1_OS_QStar-XL_20111027.01847.01847.3 | C13: 1847 | D13: 18/56 | E13: K.n[29.04]ITPAHDQNDYEVGQR.H | F13: sp|P26640|SYVC_HUMAN | G13: 1769.8337 | H13: 1851 | I13: 3 | J13: 1769.9042 | K13: 590.9518 | L13: Valine--tRNA ligase OS=Homo sapiens GN=VARS PE=1 SV=4 | M13: 4.54 | N13: 2175.76 | O13: 39.766357 | P13: 43.9 | Q13: 21.9 | R13: 8 | S13: 9.6 | T13: 5.1e-07 | U13: 0.0705 | V13: 10.2699
A14: 0.9992 | B14: MegaP_hMMP2_Tryps-1_OS_QStar-XL_20111027.01850.01850.3 | C14: 1850 | D14: 14/60 | E14: K.n[29.04]NK[156.13]EDQYDHLDAADM[147.04]TK[156.13].V | F14: sp|P34932|HSP74_HUMAN | G14: 1992.9097 | H14: 921 | I14: 3 | J14: 1992.9772 | K14: 665.3105 | L14: Heat shock 70 kDa protein 4 OS=Homo sapiens GN=HSPA4 PE=1 SV=4 | M14: 4.35 | N14: 2183.06 | O14: 33.818796 | P14: 35.3 | Q14: 27.2 | R14: 11.3 | S14: 11.4 | T14: 0.00066 | U14: 0.0675 | V14: 5.0089
A15: 0.9977 | B15: MegaP_hMMP2_Tryps-1_OS_QStar-XL_20111027.01856.01856.2 | C15: 1856 | D15: 13/16 | E15: Q.n[89.01]SGTTNK[156.13]PNK[156.13].F | F15: sp|P21333|FLNA_HUMAN,sp|P21333-2|FLNA_HUMAN | G15: 1089.5487 | H15: 1402 | I15: 2 | J15: 1089.5737 | K15: 545.7816 | L15: Filamin-A OS=Homo sapiens GN=FLNA PE=1 SV=4 | M15: 10 | N15: 2200.81 | O15: 22.902934 | P15: 39.6 | Q15: 31.5 | R15: 9.6 | S15: 11.4 | T15: 0.0052 | U15: 0.025 | V15: 4.2958
... A1142: 0.9999 | B1142: MegaP_hMMP2_Tryps-2_OS_QStar-XL_20111027.05246.05246.2 | C1142: 5246 | D1142: 16/24 | E1142: A.n[89.01]IIFIDELDAIAPK[156.13].R | F1142: sp|P55072|TERA_HUMAN | G1142: 1572.8477 | H1142: 408 | I1142: 2 | J1142: 1572.62 | K1142: 787.4311 | L1142: Transitional endoplasmic reticulum ATPase OS=Homo sapiens GN=VCP PE=1 SV=4 | M1142: 4.03 | N1142: 7178.13 | O1142: -144.58408 | P1142: 50.8 | Q1142: 27.1 | R1142: 12 | S1142: 11.9 | T1142: 6e-05 | U1142: -0.2277 | V1142: 6.7842

Sheet MMP3-T
A1: Supplementary Table 1c: Human MMP3 cleavage sites identified by PICS in trypsin-generated human proteome libraries | J1: back to index
A2: Peptides were identified by LC-MS/MS spectrum-to-sequence assignment with Mascot and X! Tandem, and further analysed by iProphet within TPP at a false-discovery rate of 1%. iProphet probability score, spectrum ID, peptide sequence, and scores by Mascot (ionscore, identity score, homology score) and X! Tandem (hyperscore, nextscore, bscore, yscore) are shown together with other peptide and peptide-spectrum match measures. One exemplary accession number of a matching UniProt protein entry is listed. K[156.13] denotes lysine labeled by heavy-dimethyl, C[160.03] and M[147.04] represent carbamidomethylated cysteine and oxidized methionine, respectively, and n[89.01] indicates thioacylated N-termini. Data were further processed and rendered non-redundant for generation of cleavage specificity profiles via WebPICS (http://clipserve.clip.ubc.ca/pics/) and iceLogo (http://iomics.ugent.be/icelogoserver/).
A3: ='MMP1-T'!A3 -> probability | B3: ='MMP1-T'!B3 -> spectrum | C3: ='MMP1-T'!C3 -> start scan | D3: ='MMP1-T'!D3 -> ions | E3: ='MMP1-T'!E3 -> peptide | F3: ='MMP1-T'!F3 -> protein | G3: ='MMP1-T'!G3 -> calculated neutral peptide mass | H3: ='MMP1-T'!H3 -> index | ... V3: ='MMP1-T'!V3 -> fval
A4: 1 | B4: MegaP_hMMP3_Tryps_AS_QStar-XL_20080308.01356.01356.4 | C4: 1356 | D4: 22/84 | E4: P.n[89.01]QQHPQQHPQNQAHGK[156.13].G | F4: sp|Q07065|CKAP4_HUMAN | G4: 1877.8707 | H4: 921 | I4: 4 | J4: 1877.8927 | K4: 470.475 | L4: Cytoskeleton-associated protein 4 OS=Homo sapiens GN=CKAP4 PE=1 SV=2 | M4: 8.77 | N4: 1422.77 | O4: 11.690313 | P4: 44.4 | Q4: 26.4 | R4: 10.1 | S4: 12.7 | T4: 5.7e-05 | U4: 0.022 | V4: 7.34
A5: 0.9992 | B5: MegaP_hMMP3_Tryps_AS_QStar-XL_20080308.01420.01420.3 | C5: 1420 | D5: 13/44 | E5: K.n[29.04]YHPDK[156.13]NPNEGEK[156.13].F | F5: sp|P31689|DNJA1_HUMAN,sp|P31689-2|DNJA1_HUMAN | G5: 1510.7416 | H5: 807 | I5: 3 | J5: 1510.7495 | K5: 504.5878 | L5: DnaJ homolog subfamily A member 1 OS=Homo sapiens GN=DNAJA1 PE=1 SV=2 | M5: 5.45 | N5: 1503.62 | O5: 5.2187812 | P5: 35.1 | Q5: 24.7 | R5: 5.9 | S5: 11.1 | T5: 0.0034 | U5: 0.0079 | V5: 5.1923
A6: 1 | B6: MegaP_hMMP3_Tryps_AS_QStar-XL_20080308.01476.01476.4 | C6: 1476 | D6: 18/72 | E6: K.n[29.04]YHTINGHNC[160.03]EVK[156.13]K[156.13].A | F6: sp|P51991|ROA3_HUMAN,sp|P51991-2|ROA3_HUMAN | G6: 1682.8567 | H6: 523 | I6: 4 | J6: 1682.882 | K6: 421.7215 | L6: Heterogeneous nuclear ribonucleoprotein A3 OS=Homo sapiens GN=HNRNPA3 PE=1 SV=2 | M6: 8.19 | N6: 1571.87 | O6: 14.99805 | P6: 34.2 | Q6: 24.6 | R6: 6.4 | S6: 9.6 | T6: 0.0016 | U6: 0.0253 | V6: 5.3281
A7: 0.9991 | B7: MegaP_hMMP3_Tryps_AS_QStar-XL_20080308.01479.01479.3 | C7: 1479 | D7: 11/44 | E7: K.n[29.04]APGTPHSHTK[156.13]PY.V | F7: sp|Q07020|RL18_HUMAN | G7: 1347.6937 | H7: 4 | I7: 3 | J7: 1347.7092 | K7: 450.2385 | L7: 60S ribosomal protein L18 OS=Homo sapiens GN=RPL18 PE=1 SV=2 | M7: 8.65 | N7: 1576.07 | O7: 11.4754 | P7: 29.7 | Q7: 20.4 | R7: 6.2 | S7: 11.7 | T7: 0.0019 | U7: 0.0155 | V7: 5.6255
A8: 1 | B8: MegaP_hMMP3_Tryps_AS_QStar-XL_20080308.01485.01485.3 | C8: 1485 | D8: 12/44 | E8: K.n[29.04]YHTVNGHNC[160.03]EVR.K | F8: sp|P09651|ROA1_HUMAN,sp|P09651-2|ROA1_HUMAN,sp|P09651-3|ROA1_HUMAN | G8: 1512.6887 | H8: 695 | I8: 3 | J8: 1512.7063 | K8: 505.2368 | L8: Heterogeneous nuclear ribonucleoprotein A1 OS=Homo sapiens GN=HNRNPA1 PE=1 SV=5 | M8: 6.91 | N8: 1586.57 | O8: 11.611717 | P8: 29.7 | Q8: 18.7 | R8: 6 | S8: 7.5 | T8: 0.00047 | U8: 0.0176 | V8: 6.7624
A9: 0.9998 | B9: MegaP_hMMP3_Tryps_AS_QStar-XL_20080308.01500.01500.3 | C9: 1500 | D9: 15/48 | E9: K.n[29.04]YHTINGHNAEVRK[156.13].A | F9: sp|P22626|ROA2_HUMAN,sp|P22626-2|ROA2_HUMAN | G9: 1593.8375 | H9: 761 | I9: 3 | J9: 1593.8474 | K9: 532.2864 | L9: Heterogeneous nuclear ribonucleoproteins A2\B1 OS=Homo sapiens GN=HNRNPA2B1 PE=1 SV=2 | M9: 8.6 | N9: 1610.72 | O9: 6.19967 | P9: 31.6 | Q9: 21.4 | R9: 7.4 | S9: 7.9 | T9: 0.001 | U9: 0.0099 | V9: 5.8222
A10: 0.991 | B10: MegaP_hMMP3_Tryps_AS_QStar-XL_20080308.01547.01547.3 | C10: 1547 | D10: 17/56 | E10: H.n[89.01]QQHHQGPPPGGPGGR.S | F10: sp|P23246|SFPQ_HUMAN,sp|P23246-2|SFPQ_HUMAN | G10: 1593.7219 | H10: 849 | I10: 3 | J10: 1593.7163 | K10: 532.2479 | L10: Splicing factor, proline- and glutamine-rich OS=Homo sapiens GN=SFPQ PE=1 SV=2 | M10: 9.76 | N10: 1682.12 | O10: -3.5071377 | P10: 38.1 | Q10: 28.6 | R10: 11 | S10: 12.1 | T10: 0.0011 | U10: -0.0056 | V10: 5.0055
A11: 0.9885 | B11: MegaP_hMMP3_Tryps_AS_QStar-XL_20080308.01549.01549.2 | C11: 1549 | D11: 12/18 | E11: A.n[89.01]QQQAAGK[156.13]EEK[156.13].S | F11: sp|Q96A49|SYAP1_HUMAN | G11: 1259.618 | H11: 6 | I11: 2 | J11: 1259.6132 | K11: 630.8163 | L11: Synapse-associated protein 1 OS=Homo sapiens GN=SYAP1 PE=1 SV=1 | M11: 6.14 | N11: 1683.17 | O11: -3.8045941 | P11: 35.5 | Q11: 32 | R11: 9.7 | S11: 10.9 | T11: 0.0057 | U11: -0.0048 | V11: 3.5133
A12: 1 | B12: MegaP_hMMP3_Tryps_AS_QStar-XL_20080308.01553.01553.3 | C12: 1553 | D12: 19/52 | E12: R.n[29.04]HEEQPAPGYDTHGR.L | F12: sp|Q07157|ZO1_HUMAN | G12: 1620.7277 | H12: 1151 | I12: 3 | J12: 1620.7444 | K12: 541.2498 | L12: Tight junction protein ZO-1 OS=Homo sapiens GN=TJP1 PE=1 SV=3 | M12: 5.27 | N12: 1691.57 | O12: 10.284838 | P12: 46.7 | Q12: 28.8 | R12: 12.8 | S12: 10.9 | T12: 2.4e-05 | U12: 0.0167 | V12: 7.9348
A13: 0.9651 | B13: MegaP_hMMP3_Tryps_AS_QStar-XL_20080308.01557.01557.4 | C13: 1557 | D13: 12/90 | E13: H.n[29.04]LVAITGNVPNAIPENK[156.13].D | F13: sp|Q9Y5C1|ANGL3_HUMAN | G13: 1704.9777 | H13: 7 | I13: 4 | J13: 1704.9972 | K13: 427.2517 | L13: Angiopoietin-related protein 3 OS=Homo sapiens GN=ANGPTL3 PE=1 SV=1 | M13: 6 | N13: 1695.77 | O13: 11.410136 | P13: 27 | Q13: 23.8 | R13: 11.2 | S13: 11.3 | T13: 0.4 | U13: 0.0195 | V13: 1.2507
A14: 1 | B14: MegaP_hMMP3_Tryps_AS_QStar-XL_20080308.01560.01560.4 | C14: 1560 | D14: 18/72 | E14: R.n[29.04]HLVYESDK[156.13]NK[156.13]DEK[156.13].L | F14: sp|Q15293|RCN1_HUMAN | G14: 1715.9097 | H14: 525 | I14: 4 | J14: 1715.9273 | K14: 429.9847 | L14: Reticulocalbin-1 OS=Homo sapiens GN=RCN1 PE=1 SV=1 | M14: 5.48 | N14: 1701.02 | O14: 10.232922 | P14: 34.5 | Q14: 22.4 | R14: 9.3 | S14: 12.1 | T14: 0.0013 | U14: 0.0176 | V14: 5.8317
A15: 0.9978 | B15: MegaP_hMMP3_Tryps_AS_QStar-XL_20080308.01563.01563.3 | C15: 1563 | D15: 17/56 | E15: H.n[89.01]QQHHQGPPPGGPGGR.S | F15: sp|P23246|SFPQ_HUMAN,sp|P23246-2|SFPQ_HUMAN | G15: 1593.7219 | H15: 806 | I15: 3 | J15: 1593.725 | K15: 532.2479 | L15: Splicing factor, proline- and glutamine-rich OS=Homo sapiens GN=SFPQ PE=1 SV=2 | M15: 9.76 | N15: 1708.37 | O15: 1.9414512 | P15: 37.7 | Q15: 23.3 | R15: 11.1 | S15: 12 | T15: 0.00069 | U15: 0.0031 | V15: 5.9312
... A442: 0.9944 | B442: MegaP_hMMP3_Tryps_AS_QStar-XL_20080308.05069.05069.2 | C442: 5069 | D442: 10/26 | E442: D.n[89.01]LAGNSEVILPVPAF.N | F442: sp|P06733|ENOA_HUMAN | G442: 1513.7847 | H442: 1334 | I442: 2 | J442: 1513.7613 | K442: 757.8996 | L442: Alpha-enolase OS=Homo sapiens GN=ENO1 PE=1 SV=2 | M442: 4 | N442: 7334.89 | O442: -15.437401 | P442: 30.9 | Q442: 27.5 | R442: 9.5 | S442: 12.7 | T442: 0.00042 | U442: -0.0234 | V442: 4.1954

Sheet MMP7-T
A1: Supplementary Table 1d: Human MMP7 cleavage sites identified by PICS in trypsin-generated human proteome libraries | J1: back to index
A2: Peptides were identified by LC-MS/MS spectrum-to-sequence assignment with Mascot and X! Tandem, and further analysed by iProphet within TPP at a false-discovery rate of 1%. iProphet probability score, spectrum ID, peptide sequence, and scores by Mascot (ionscore, identity score, homology score) and X! Tandem (hyperscore, nextscore, bscore, yscore) are shown together with other peptide and peptide-spectrum match measures. One exemplary accession number of a matching UniProt protein entry is listed. K[156.13] denotes lysine labeled by heavy-dimethyl, C[160.03] and M[147.04] represent carbamidomethylated cysteine and oxidized methionine, respectively, and n[89.01] indicates thioacylated N-termini. Data were further processed and rendered non-redundant for generation of cleavage specificity profiles via WebPICS (http://clipserve.clip.ubc.ca/pics/) and iceLogo (http://iomics.ugent.be/icelogoserver/).
A3: ='MMP1-T'!A3 -> probability | B3: ='MMP1-T'!B3 -> spectrum | C3: ='MMP1-T'!C3 -> start scan | D3: ='MMP1-T'!D3 -> ions | E3: ='MMP1-T'!E3 -> peptide | F3: ='MMP1-T'!F3 -> protein | G3: ='MMP1-T'!G3 -> calculated neutral peptide mass | H3: ='MMP1-T'!H3 -> index | ... V3: ='MMP1-T'!V3 -> fval
A4: 0.9998 | B4: MegaP_hMMP7_Tryps_OS_QStar-Pulsar_20080112.01377.01377.4 | C4: 1377 | D4: 17/102 | E4: A.n[29.04]AENEEDEHSVNYK[156.13]PPAQK[156.13].S | F4: sp|P52565|GDIR1_HUMAN,sp|P52565-2|GDIR1_HUMAN | G4: 2168.0387 | H4: 507 | I4: 4 | J4: 2168.2098 | K4: 543.017 | L4: Rho GDP-dissociation inhibitor 1 OS=Homo sapiens GN=ARHGDIA PE=1 SV=3 | M4: 4.57 | N4: 1436.52 | O4: 78.772856 | P4: 36.6 | Q4: 25.3 | R4: 11.3 | S4: 12.5 | T4: 1.9e-05 | U4: 0.1711 | V4: 6.7801
A5: 1 | B5: MegaP_hMMP7_Tryps_OS_QStar-Pulsar_20080112.01419.01419.4 | C5: 1419 | D5: 22/138 | E5: K.n[29.04]APK[156.13]PDGPGGGPGGSHMGGNYGDDR.R | F5: sp|P35637|FUS_HUMAN,sp|P35637-2|FUS_HUMAN | G5: 2308.0287 | H5: 508 | I5: 4 | J5: 2308.0939 | K5: 578.0145 | L5: RNA-binding protein FUS OS=Homo sapiens GN=FUS PE=1 SV=1 | M5: 5.3 | N5: 1514.5 | O5: 28.199985 | P5: 48.4 | Q5: 22.3 | R5: 8.6 | S5: 11.7 | T5: 1.9e-08 | U5: 0.0652 | V5: 9.6597
A6: 0.9972 | B6: MegaP_hMMP7_Tryps_OS_QStar-Pulsar_20080112.01421.01421.4 | C6: 1421 | D6: 16/96 | E6: K.n[29.04]LSHSDEK[156.13]PYQC[160.03]PVC[160.03]QQR.F | F6: sp|P56270|MAZ_HUMAN,sp|P56270-2|MAZ_HUMAN,sp|P56270-3|MAZ_HUMAN | G6: 2187.0197 | H6: 1006 | I6: 4 | J6: 2187.1344 | K6: 547.7622 | L6: Myc-associated zinc finger protein OS=Homo sapiens GN=MAZ PE=1 SV=1 | M6: 6.73 | N6: 1523.82 | O6: 52.349359 | P6: 32 | Q6: 23.4 | R6: 11.3 | S6: 11.6 | T6: 0.0046 | U6: 0.1147 | V6: 4.1141
A7: 0.9681 | B7: MegaP_hMMP7_Tryps_OS_QStar-Pulsar_20080112.01427.01427.4 | C7: 1427 | D7: 12/138 | E7: K.n[29.04]APK[156.13]PDGPGGGPGGSHMGGNYGDDR.R | F7: sp|P35637|FUS_HUMAN,sp|P35637-2|FUS_HUMAN | G7: 2308.0287 | H7: 1091 | I7: 4 | J7: 2308.0799 | K7: 578.0145 | L7: RNA-binding protein FUS OS=Homo sapiens GN=FUS PE=1 SV=1 | M7: 5.3 | N7: 1538.36 | O7: 22.144773 | P7: 27.2 | Q7: 20.6 | R7: 7.9 | S7: 10.9 | T7: 0.029 | U7: 0.0512 | V7: 2.636
A8: 0.9707 | B8: MegaP_hMMP7_Tryps_OS_QStar-Pulsar_20080112.01453.01453.4 | C8: 1453 | D8: 12/138 | E8: K.n[29.04]APK[156.13]PDGPGGGPGGSHMGGNYGDDR.R | F8: sp|P35637|FUS_HUMAN,sp|P35637-2|FUS_HUMAN | G8: 2308.0287 | H8: 1002 | I8: 4 | J8: 2308.1779 | K8: 578.0145 | L8: RNA-binding protein FUS OS=Homo sapiens GN=FUS PE=1 SV=1 | M8: 5.3 | N8: 1606.68 | O8: 64.531253 | P8: 29.6 | Q8: 22 | R8: 11 | S8: 12.4 | T8: 0.03 | U8: 0.1492 | V8: 2.6798
A9: 0.9901 | B9: MegaP_hMMP7_Tryps_OS_QStar-Pulsar_20080112.01487.01487.4 | C9: 1487 | D9: 19/234 | E9: K.n[29.04]TDNAGDQHGGGGGGGGGAGAAGGGGGGENYDDPHK[156.13]TPASP.V | F9: sp|P14866|HNRPL_HUMAN | G9: 3489.4797 | H9: 1084 | I9: 4 | J9: 3490.5497 | K9: 873.3772 | L9: Heterogeneous nuclear ribonucleoprotein L OS=Homo sapiens GN=HNRNPL PE=1 SV=2 | M9: 4.34 | N9: 1693.79 | O9: 19.076809 | P9: 43 | Q9: 25.1 | R9: 12.9 | S9: 13.8 | T9: 3.2e-06 | U9: 1.07 | V9: 5.5174
A10: 0.9994 | B10: MegaP_hMMP7_Tryps_OS_QStar-Pulsar_20080112.01501.01501.4 | C10: 1501 | D10: 17/96 | E10: R.n[29.04]ASGNYATVISHNPETK[156.13]K[156.13].T | F10: sp|P62917|RL8_HUMAN | G10: 1900.0057 | H10: 1056 | I10: 4 | J10: 1900.0992 | K10: 476.0087 | L10: 60S ribosomal protein L8 OS=Homo sapiens GN=RPL8 PE=1 SV=2 | M10: 8.55 | N10: 1731.09 | O10: 49.106245 | P10: 39.3 | Q10: 28.8 | R10: 10.4 | S10: 12.4 | T10: 0.00015 | U10: 0.0935 | V10: 5.767
A11: 0.9857 | B11: MegaP_hMMP7_Tryps_OS_QStar-Pulsar_20080112.01503.01503.3 | C11: 1503 | D11: 15/40 | E11: G.n[89.01]IK[156.13]EDTEEHHLR.D | F11: sp|Q32P51|RA1L2_HUMAN,sp|P09651|ROA1_HUMAN,sp|P09651-2|ROA1_HUMAN,sp|P09651-3|ROA1_HUMAN,sp|P22626|ROA2_HUMAN,sp|P22626-2|ROA2_HUMAN | G11: 1521.7247 | H11: 512 | I11: 3 | J11: 1521.7846 | K11: 508.2488 | L11: Heterogeneous nuclear ribonucleoprotein A1-like 2 OS=Homo sapiens GN=HNRNPA1L2 PE=2 SV=2 | M11: 5.36 | N11: 1732.11 | O11: 39.285221 | P11: 34.3 | Q11: 28.8 | R11: 9.8 | S11: 11.6 | T11: 0.01 | U11: 0.0599 | V11: 3.944
A12: 1 | B12: MegaP_hMMP7_Tryps_OS_QStar-Pulsar_20080112.01524.01524.3 | C12: 1524 | D12: 17/56 | E12: K.n[29.04]ITPAHDQNDYEVGQR.H | F12: sp|P26640|SYVC_HUMAN | G12: 1769.8337 | H12: 513 | I12: 3 | J12: 1769.9053 | K12: 590.9518 | L12: Valine--tRNA ligase OS=Homo sapiens GN=VARS PE=1 SV=4 | M12: 4.54 | N12: 1783.95 | O12: 40.386825 | P12: 39.6 | Q12: 21.3 | R12: 7.8 | S12: 11.1 | T12: 3.5e-06 | U12: 0.0716 | V12: 9.0738
A13: 0.9964 | B13: MegaP_hMMP7_Tryps_OS_QStar-Pulsar_20080112.01532.01532.4 | C13: 1532 | D13: 19/90 | E13: R.n[29.04]TYEEGLK[156.13]HEANNPQLK[156.13].E | F13: sp|P31948|STIP1_HUMAN | G13: 1954.0157 | H13: 1053 | I13: 4 | J13: 1954.0752 | K13: 489.5112 | L13: Stress-induced-phosphoprotein 1 OS=Homo sapiens GN=STIP1 PE=1 SV=1 | M13: 5.46 | N13: 1810.99 | O13: 30.387456 | P13: 35.1 | Q13: 26.4 | R13: 12.3 | S13: 13.4 | T13: 0.0024 | U13: 0.0595 | V13: 4.4555
A14: 0.9989 | B14: MegaP_hMMP7_Tryps_OS_QStar-Pulsar_20080112.01547.01547.3 | C14: 1547 | D14: 16/52 | E14: Y.n[29.04]VAEYHSEPVEDEK[156.13]P.- | F14: sp|P26196|DDX6_HUMAN | G14: 1683.7987 | H14: 1136 | I14: 3 | J14: 1683.8678 | K14: 562.2735 | L14: Probable ATP-dependent RNA helicase DDX6 OS=Homo sapiens GN=DDX6 PE=1 SV=2 | M14: 4.25 | N14: 1846.22 | O14: 40.964643 | P14: 37.6 | Q14: 27.8 | R14: 11.6 | S14: 12.8 | T14: 0.0054 | U14: 0.0691 | V14: 4.3841
A15: 1 | B15: MegaP_hMMP7_Tryps_OS_QStar-Pulsar_20080112.01556.01556.4 | C15: 1556 | D15: 21/90 | E15: R.n[29.04]LNFSHGTHEYHAETIK[156.13].N | F15: sp|P14618|KPYM_HUMAN,sp|P14618-2|KPYM_HUMAN | G15: 1938.9587 | H15: 515 | I15: 4 | J15: 1939.0389 | K15: 485.747 | L15: Pyruvate kinase PKM OS=Homo sapiens GN=PKM PE=1 SV=4 | M15: 6.27 | N15: 1867.04 | O15: 41.276632 | P15: 42.6 | Q15: 26 | R15: 8.4 | S15: 10.3 | T15: 7.5e-06 | U15: 0.0802 | V15: 8.0487
... A497: 0.9303 | B497: MegaP_hMMP7_Tryps_OS_QStar-Pulsar_20080112.05046.05046.2 | C497: 5046 | D497: 12/18 | E497: E.n[89.01]LVDSVLDVVR.K | F497: sp|P07437|TBB5_HUMAN,sp|Q13885|TBB2A_HUMAN,sp|Q9BVA1|TBB2B_HUMAN,sp|Q13509|TBB3_HUMAN,sp|P68371|TBB4B_HUMAN | G497: 1201.6377 | H497: 774 | I497: 2 | J497: 1201.7048 | K497: 601.8261 | L497: Tubulin beta chain OS=Homo sapiens GN=TUBB PE=1 SV=2 | M497: 4.21 | N497: 5991.57 | O497: 55.747001 | P497: 37.6 | Q497: 33.7 | R497: 11.1 | S497: 13.2 | T497: 0.04 | U497: 0.0671 | V497: 2.5534

Sheet MMP8-T
A1: Supplementary Table 1e: Human MMP8 cleavage sites identified by PICS in trypsin-generated human proteome libraries | J1: back to index
A2: Peptides were identified by LC-MS/MS spectrum-to-sequence assignment with Mascot and X! Tandem, and further analysed by iProphet within TPP at a false-discovery rate of 1%. iProphet probability score, spectrum ID, peptide sequence, and scores by Mascot (ionscore, identity score, homology score) and X! Tandem (hyperscore, nextscore, bscore, yscore) are shown together with other peptide and peptide-spectrum match measures. One exemplary accession number of a matching UniProt protein entry is listed. K[156.13] denotes lysine labeled by heavy-dimethyl, C[160.03] and M[147.04] represent carbamidomethylated cysteine and oxidized methionine, respectively, and n[89.01] indicates thioacylated N-termini. Data were further processed and rendered non-redundant for generation of cleavage specificity profiles via WebPICS (http://clipserve.clip.ubc.ca/pics/) and iceLogo (http://iomics.ugent.be/icelogoserver/).
A3: ='MMP1-T'!A3 -> probability | B3: ='MMP1-T'!B3 -> spectrum | C3: ='MMP1-T'!C3 -> start scan | D3: ='MMP1-T'!D3 -> ions | E3: ='MMP1-T'!E3 -> peptide | F3: ='MMP1-T'!F3 -> protein | G3: ='MMP1-T'!G3 -> calculated neutral peptide mass | H3: ='MMP1-T'!H3 -> index | ... V3: ='MMP1-T'!V3 -> fval
A4: 0.9668 | B4: MegaP_hMMP8_Tryps_TK_QStar-XL_20110716.02057.02057.2 | C4: 2057 | D4: 6/14 | E4: S.n[89.01]PC[160.03]AAC[160.03]ADR.L | F4: sp|Q9Y235|ABEC2_HUMAN | G4: 1007.3627 | H4: 263 | I4: 2 | J4: 1007.166 | K4: 504.6886 | L4: Probable C- U-editing enzyme APOBEC-2 OS=Homo sapiens GN=APOBEC2 PE=1 SV=1 | M4: 6.18 | N4: 2167.62 | O4: -194.87264 | P4: 19.5 | Q4: 13.4 | R4: 0 | S4: 8.1 | T4: 0.13 | U4: -0.1967 | V4: 3.3237
A5: 1 | B5: MegaP_hMMP8_Tryps_TK_QStar-XL_20110716.02057.02057.3 | C5: 2057 | D5: 14/44 | E5: K.n[29.04]YHPDK[156.13]NPNEGEK[156.13].F | F5: sp|P31689|DNJA1_HUMAN,sp|P31689-2|DNJA1_HUMAN | G5: 1510.7416 | H5: 1009 | I5: 3 | J5: 1510.749 | K5: 504.5878 | L5: DnaJ homolog subfamily A member 1 OS=Homo sapiens GN=DNAJA1 PE=1 SV=2 | M5: 5.45 | N5: 2167.62 | O5: 4.8884786 | P5: 39.9 | Q5: 21.9 | R5: 9.4 | S5: 11.7 | T5: 2.5e-05 | U5: 0.0074 | V5: 8.9226
A6: 0.9999 | B6: MegaP_hMMP8_Tryps_TK_QStar-XL_20110716.02062.02062.4 | C6: 2062 | D6: 16/84 | E6: K.n[29.04]SEESSHYSTEK[156.13]ESEK[156.13].T | F6: sp|P55265|DSRAD_HUMAN,sp|P55265-2|DSRAD_HUMAN,sp|P55265-3|DSRAD_HUMAN,sp|P55265-4|DSRAD_HUMAN,sp|P55265-5|DSRAD_HUMAN | G6: 1839.8377 | H6: 1016 | I6: 4 | J6: 1839.8582 | K6: 460.9667 | L6: Double-stranded RNA-specific adenosine deaminase OS=Homo sapiens GN=ADAR PE=1 SV=4 | M6: 4.64 | N6: 2174.97 | O6: 11.11794 | P6: 38.2 | Q6: 23.8 | R6: 7.7 | S6: 11.8 | T6: 7.5e-05 | U6: 0.0205 | V6: 7.0514
A7: 0.9998 | B7: MegaP_hMMP8_Tryps_TK_QStar-XL_20110716.02071.02071.4 | C7: 2071 | D7: 13/78 | E7: K.n[29.04]APGTPHSHTK[156.13]PYVR.S | F7: sp|Q07020|RL18_HUMAN | G7: 1602.8627 | H7: 731 | I7: 4 | J7: 1602.8826 | K7: 401.723 | L7: 60S ribosomal protein L18 OS=Homo sapiens GN=RPL18 PE=1 SV=2 | M7: 10 | N7: 2187.52 | O7: 12.384155 | P7: 30.4 | Q7: 22.2 | R7: 7 | S7: 12.5 | T7: 0.0058 | U7: 0.0199 | V7: 4.3945
A8: 0.9983 | B8: MegaP_hMMP8_Tryps_TK_QStar-XL_20110716.02075.02075.4 | C8: 2075 | D8: 13/78 | E8: R.n[29.04]YHPDK[156.13]NK[156.13]EPGAEEK[156.13].F | F8: sp|P25685|DNJB1_HUMAN | G8: 1752.9047 | H8: 732 | I8: 4 | J8: 1752.9317 | K8: 439.2335 | L8: DnaJ homolog subfamily B member 1 OS=Homo sapiens GN=DNAJB1 PE=1 SV=4 | M8: 5.53 | N8: 2190.67 | O8: 15.36768 | P8: 29.9 | Q8: 22.2 | R8: 0 | S8: 12 | T8: 0.072 | U8: 0.027 | V8: 2.9829
A9: 0.9999 | B9: MegaP_hMMP8_Tryps_TK_QStar-XL_20110716.02089.02089.3 | C9: 2089 | D9: 10/44 | E9: K.n[29.04]APGTPHSHTK[156.13]PY.V | F9: sp|Q07020|RL18_HUMAN | G9: 1347.6935 | H9: 420 | I9: 3 | J9: 1347.6925 | K9: 450.2384 | L9: 60S ribosomal protein L18 OS=Homo sapiens GN=RPL18 PE=1 SV=2 | M9: 8.65 | N9: 2219.67 | O9: -0.74034852 | P9: 30.8 | Q9: 20 | R9: 0 | S9: 12.8 | T9: 0.00038 | U9: -0.001 | V9: 6.7713
A10: 0.9999 | B10: MegaP_hMMP8_Tryps_TK_QStar-XL_20110716.02097.02097.3 | C10: 2097 | D10: 16/44 | E10: F.n[29.04]SAPK[156.13]PQTSPSPK[156.13].R | F10: sp|Q01518-2|CAP1_HUMAN,sp|Q01518|CAP1_HUMAN | G10: 1307.7447 | H10: 998 | I10: 3 | J10: 1307.7347 | K10: 436.9222 | L10: Isoform 2 of Adenylyl cyclase-associated protein 1 OS=Homo sapiens GN=CAP1 | M10: 10 | N10: 2236.27 | O10: -7.6291233 | P10: 43.4 | Q10: 30.7 | R10: 9.8 | S10: 12.5 | T10: 5.7e-05 | U10: -0.01 | V10: 7.5316
A11: 0.9907 | B11: MegaP_hMMP8_Tryps_TK_QStar-XL_20110716.02105.02105.3 | C11: 2105 | D11: 14/40 | E11: K.n[29.04]K[156.13]YVHADAPTNK[156.13].T | F11: sp|Q92922|SMRC1_HUMAN | G11: 1326.7296 | H11: 422 | I11: 3 | J11: 1326.7289 | K11: 443.2505 | L11: SWI\SNF complex subunit SMARCC1 OS=Homo sapiens GN=SMARCC1 PE=1 SV=3 | M11: 8.51 | N11: 2248.67 | O11: -0.52641415 | P11: 33.8 | Q11: 30 | R11: 11 | S11: 12 | T11: 0.15 | U11: -0.0007 | V11: 2.022
A12: 0.9994 | B12: MegaP_hMMP8_Tryps_TK_QStar-XL_20110716.02130.02130.3 | C12: 2130 | D12: 15/56 | E12: L.n[89.01]C[160.03]TGESGAGK[156.13]TENTK[156.13]K[156.13].V | F12: sp|P35579|MYH9_HUMAN,sp|P35580|MYH10_HUMAN,sp|P35580-2|MYH10_HUMAN,sp|P35580-3|MYH10_HUMAN,sp|P35580-4|MYH10_HUMAN,sp|P35749|MYH11_HUMAN,sp|P35749-2|MYH11_HUMAN,sp|P35749-3|MYH11_HUMAN,sp|P35749-4|MYH11_HUMAN,sp|Q7Z406|MYH14_HUMAN,sp|Q7Z406-2|MYH14_HUMAN,sp|Q7Z406-4|MYH14_HUMAN,sp|Q7Z406-5|MYH14_HUMAN,sp|Q7Z406-6|MYH14_HUMAN,sp|P35579-2|MYH9_HUMAN | G12: 1738.8229 | H12: 736 | I12: 3 | J12: 1738.8235 | K12: 580.6149 | L12: Myosin-9 OS=Homo sapiens GN=MYH9 PE=1 SV=4 | M12: 8.18 | N12: 2292.22 | O12: 0.3444624 | P12: 41.1 | Q12: 22.6 | R12: 5.8 | S12: 11.2 | T12: 2e-05 | U12: 0.0006 | V12: 8.1117
A13: 0.992 | B13: MegaP_hMMP8_Tryps_TK_QStar-XL_20110716.02133.02133.3 | C13: 2133 | D13: 7/60 | E13: R.n[29.04]SVSGASNHQPNSNSGR.Y | F13: sp|Q9NSE4|SYIM_HUMAN | G13: 1625.7507 | H13: 737 | I13: 3 | J13: 1626.7165 | K13: 542.9242 | L13: Isoleucine--tRNA ligase, mitochondrial OS=Homo sapiens GN=IARS2 PE=1 SV=2 | M13: 9.49 | N13: 2299.47 | O13: -23.05724 | P13: 26.9 | Q13: 18.8 | R13: 0 | S13: 12 | T13: 0.019 | U13: 0.9658 | V13: 3.6872
A14: 0.9983 | B14: MegaP_hMMP8_Tryps_TK_QStar-XL_20110716.02142.02142.2 | C14: 2142 | D14: 15/18 | E14: A.n[89.01]QK[156.13]AEGAGDAK[156.13].- | F14: sp|P05204|HMGN2_HUMAN | G14: 1117.5437 | H14: 1433 | I14: 2 | J14: 1117.5481 | K14: 559.7791 | L14: Non-histone chromosomal protein HMG-17 OS=Homo sapiens GN=HMGN2 PE=1 SV=3 | M14: 6.07 | N14: 2313.97 | O14: 3.9301217 | P14: 45.9 | Q14: 28.2 | R14: 11.1 | S14: 10.9 | T14: 0.0011 | U14: 0.0044 | V14: 5.798
A15: 0.9455 | B15: MegaP_hMMP8_Tryps_TK_QStar-XL_20110716.02146.02146.4 | C15: 2146 | D15: 19/72 | E15: R.n[29.04]HLVYESDK[156.13]NK[156.13]DEK[156.13].L | F15: sp|Q15293|RCN1_HUMAN | G15: 1715.9094 | H15: 361 | I15: 4 | J15: 1715.911 | K15: 429.9846 | L15: Reticulocalbin-1 OS=Homo sapiens GN=RCN1 PE=1 SV=1 | M15: 5.48 | N15: 2325.37 | O15: 0.93026587 | P15: 32.8 | Q15: 25.9 | R15: 10.5 | S15: 12.6 | T15: 0.093 | U15: 0.0016 | V15: 2.6844
... A690: 0.9708 | B690: MegaP_hMMP8_Tryps_TK_QStar-XL_20110716.06294.06294.2 | C690: 6294 | D690: 12/16 | E690: C.n[89.01]LISGWGNTK[156.13].S | F690: CON_P00761|P00761 | G690: 1090.5477 | H690: 1356 | I690: 2 | J690: 1090.5651 | K690: 546.2811 | L690: TRYP_PIG Trypsin - Sus scrofa (Pig). | M690: 8.75 | N690: 9476.67 | O690: 15.925867 | P690: 38.3 | Q690: 28.6 | R690: 10.8 | S690: 12.3 | T690: 0.027 | U690: 0.0174 | V690: 3.6771

Sheet MMP9-T
A1: Supplementary Table 1f: Human MMP9 cleavage sites identified by PICS in trypsin-generated human proteome libraries | J1: back to index
A2: Peptides were identified by LC-MS/MS spectrum-to-sequence assignment with Mascot and X! Tandem, and further analysed by iProphet within TPP at a false-discovery rate of 1%. iProphet probability score, spectrum ID, peptide sequence, and scores by Mascot (ionscore, identity score, homology score) and X! Tandem (hyperscore, nextscore, bscore, yscore) are shown together with other peptide and peptide-spectrum match measures. One exemplary accession number of a matching UniProt protein entry is listed. K[156.13] denotes lysine labeled by heavy-dimethyl, C[160.03] and M[147.04] represent carbamidomethylated cysteine and oxidized methionine, respectively, and n[89.01] indicates thioacylated N-termini. Data were further processed and rendered non-redundant for generation of cleavage specificity profiles via WebPICS (http://clipserve.clip.ubc.ca/pics/) and iceLogo (http://iomics.ugent.be/icelogoserver/).
A3: ='MMP1-T'!A3 -> probability | B3: ='MMP1-T'!B3 -> spectrum | C3: ='MMP1-T'!C3 -> start scan | D3: ='MMP1-T'!D3 -> ions | E3: ='MMP1-T'!E3 -> peptide | F3: ='MMP1-T'!F3 -> protein | G3: ='MMP1-T'!G3 -> calculated neutral peptide mass | H3: ='MMP1-T'!H3 -> index | ... V3: ='MMP1-T'!V3 -> fval
A4: 0.994 | B4: MegaP_hMMP9_Tryps_AP_QStar-XL_20080502.01472.01472.4 | C4: 1472 | D4: 18/84 | E4: P.n[89.01]QQHPQQHPQNQAHGK[156.13].G | F4: sp|Q07065|CKAP4_HUMAN | G4: 1877.8703 | H4: 489 | I4: 4 | J4: 1877.8608 | K4: 470.4749 | L4: Cytoskeleton-associated protein 4 OS=Homo sapiens GN=CKAP4 PE=1 SV=2 | M4: 8.77 | N4: 1544.65 | O4: -5.0480908 | P4: 37.2 | Q4: 26.4 | R4: 10.9 | S4: 12.5 | T4: 0.017 | U4: -0.0095 | V4: 3.8033
A5: 0.9887 | B5: MegaP_hMMP9_Tryps_AP_QStar-XL_20080502.01621.01621.4 | C5: 1621 | D5: 17/84 | E5: R.n[89.01]INVVAAMFSAPPFPA.A | F5: sp|A5PKW4|PSD1_HUMAN,sp|A5PKW4-2|PSD1_HUMAN | G5: 1618.7887 | H5: 490 | I5: 4 | J5: 1618.9215 | K5: 405.7045 | L5: PH and SEC7 domain-containing protein 1 OS=Homo sapiens GN=PSD PE=1 SV=2 | M5: 5.52 | N5: 1704.25 | O5: 81.83296 | P5: 31.3 | Q5: 22.3 | R5: 10.9 | S5: 11.3 | T5: 0.012 | U5: 0.1328 | V5: 3.9688
A6: 0.9985 | B6: MegaP_hMMP9_Tryps_AP_QStar-XL_20080502.01666.01666.3 | C6: 1666 | D6: 12/44 | E6: K.n[29.04]APGTPHSHTK[156.13]PY.V | F6: sp|Q07020|RL18_HUMAN | G6: 1347.6937 | H6: 821 | I6: 3 | J6: 1347.6631 | K6: 450.2385 | L6: 60S ribosomal protein L18 OS=Homo sapiens GN=RPL18 PE=1 SV=2 | M6: 8.65 | N6: 1767.25 | O6: -22.65466 | P6: 29.3 | Q6: 18.7 | R6: 3.5 | S6: 11.5 | T6: 0.0007 | U6: -0.0306 | V6: 6.4828
A7: 1 | B7: MegaP_hMMP9_Tryps_AP_QStar-XL_20080502.01674.01674.3 | C7: 1674 | D7: 12/44 | E7: K.n[29.04]YHTVNGHNC[160.03]EVR.K | F7: sp|P09651|ROA1_HUMAN,sp|P09651-2|ROA1_HUMAN,sp|P09651-3|ROA1_HUMAN | G7: 1512.6887 | H7: 492 | I7: 3 | J7: 1512.6648 | K7: 505.2368 | L7: Heterogeneous nuclear ribonucleoprotein A1 OS=Homo sapiens GN=HNRNPA1 PE=1 SV=5 | M7: 6.91 | N7: 1775.65 | O7: -15.768184 | P7: 30.4 | Q7: 17.8 | R7: 6.3 | S7: 8.5 | T7: 0.00075 | U7: -0.0239 | V7: 6.7473
A8: 0.941 | B8: MegaP_hMMP9_Tryps_AP_QStar-XL_20080502.01734.01734.4 | C8: 1734 | D8: 13/90 | E8: R.n[89.01]AALSPAGALLLQPPAR.R | F8: sp|Q96JY6-5|PDLI2_HUMAN | G8: 1632.9017 | H8: 494 | I8: 4 | J8: 1632.9451 | K8: 409.2327 | L8: Isoform 5 of PDZ and LIM domain protein 2 OS=Homo sapiens GN=PDLIM2 | M8: 9.79 | N8: 1859.65 | O8: 26.513033 | P8: 26.3 | Q8: 24.3 | R8: 11.3 | S8: 11.2 | T8: 0.13 | U8: 0.0434 | V8: 1.6003
A9: 0.9999 | B9: MegaP_hMMP9_Tryps_AP_QStar-XL_20080502.01756.01756.3 | C9: 1756 | D9: 21/56 | E9: H.n[89.01]QQHHQGPPPGGPGGR.S | F9: sp|P23246|SFPQ_HUMAN | G9: 1593.7217 | H9: 1222 | I9: 3 | J9: 1593.6864 | K9: 532.2478 | L9: Splicing factor, proline- and glutamine-rich OS=Homo sapiens GN=SFPQ PE=1 SV=2 | M9: 9.76 | N9: 1897.46 | O9: -22.107497 | P9: 49.2 | Q9: 27.2 | R9: 10.8 | S9: 12.1 | T9: 2.4e-05 | U9: -0.0353 | V9: 8.0023
A10: 0.999 | B10: MegaP_hMMP9_Tryps_AP_QStar-XL_20080502.01757.01757.4 | C10: 1757 | D10: 19/78 | E10: R.n[89.01]K[156.13]SAPATGGVK[156.13]K[156.13]PHR.Y | F10: sp|Q16695|H31T_HUMAN,sp|P68431|H31_HUMAN,sp|Q71DI3|H32_HUMAN | G10: 1604.9184 | H10: 497 | I10: 4 | J10: 1604.9262 | K10: 402.2369 | L10: Histone H3.1t OS=Homo sapiens GN=HIST3H3 PE=1 SV=3 | M10: 11.26 | N10: 1893.26 | O10: 4.8478894 | P10: 34.4 | Q10: 23.6 | R10: 11.1 | S10: 10.3 | T10: 0.0044 | U10: 0.0078 | V10: 4.7786
A11: 1 | B11: MegaP_hMMP9_Tryps_AP_QStar-XL_20080502.01776.01776.3 | C11: 1776 | D11: 22/56 | E11: H.n[89.01]QQHHQGPPPGGPGGR.S | F11: sp|P23246|SFPQ_HUMAN | G11: 1593.7217 | H11: 1033 | I11: 3 | J11: 1593.6873 | K11: 532.2478 | L11: Splicing factor, proline- and glutamine-rich OS=Homo sapiens GN=SFPQ PE=1 SV=2 | M11: 9.76 | N11: 1925.81 | O11: -21.54385 | P11: 52.1 | Q11: 26.8 | R11: 10.3 | S11: 11.7 | T11: 2.8e-06 | U11: -0.0344 | V11: 9.3103
A12: 0.9961 | B12: MegaP_hMMP9_Tryps_AP_QStar-XL_20080502.01797.01797.3 | C12: 1797 | D12: 19/56 | E12: H.n[89.01]QQHHQGPPPGGPGGR.S | F12: sp|P23246|SFPQ_HUMAN,sp|P23246-2|SFPQ_HUMAN | G12: 1593.7217 | H12: 498 | I12: 3 | J12: 1593.678 | K12: 532.2478 | L12: Splicing factor, proline- and glutamine-rich OS=Homo sapiens GN=SFPQ PE=1 SV=2 | M12: 9.76 | N12: 1959.41 | O12: -27.368205 | P12: 42.7 | Q12: 25.3 | R12: 10.2 | S12: 11.6 | T12: 0.001 | U12: -0.0437 | V12: 5.8714
A13: 0.9999 | B13: MegaP_hMMP9_Tryps_AP_QStar-XL_20080502.01803.01803.3 | C13: 1803 | D13: 13/44 | E13: K.n[29.04]YHTINGHNC[160.03]EVK[156.13].K | F13: sp|P51991|ROA3_HUMAN,sp|P51991-2|ROA3_HUMAN | G13: 1526.7297 | H13: 864 | I13: 3 | J13: 1526.7041 | K13: 509.9172 | L13: Heterogeneous nuclear ribonucleoprotein A3 OS=Homo sapiens GN=HNRNPA3 PE=1 SV=2 | M13: 6.91 | N13: 1972.01 | O13: -16.734743 | P13: 28.3 | Q13: 16.9 | R13: 6.4 | S13: 7.5 | T13: 0.0061 | U13: -0.0256 | V13: 5.4699
A14: 1 | B14: MegaP_hMMP9_Tryps_AP_QStar-XL_20080502.01806.01806.3 | C14: 1806 | D14: 15/44 | E14: R.n[29.04]AQHEDQVEQYK[156.13]K[156.13].E | F14: sp|P02545|LMNA_HUMAN,sp|P02545-2|LMNA_HUMAN,sp|P02545-3|LMNA_HUMAN,sp|P02545-4|LMNA_HUMAN | G14: 1585.8097 | H14: 782 | I14: 3 | J14: 1585.7711 | K14: 529.6105 | L14: Prelamin-A\C OS=Homo sapiens GN=LMNA PE=1 SV=1 | M14: 5.45 | N14: 1977.26 | O14: -24.294584 | P14: 32.8 | Q14: 21.1 | R14: 11.5 | S14: 11.5 | T14: 0.00031 | U14: -0.0386 | V14: 6.9238
A15: 0.9914 | B15: MegaP_hMMP9_Tryps_AP_QStar-XL_20080502.01823.01823.3 | C15: 1823 | D15: 16/52 | E15: G.n[89.01]SC[160.03]AC[160.03]AGSC[160.03]K[156.13]C[160.03]K[156.13]EC[160.03]K[156.13].C | F15: sp|P07438|MT1B_HUMAN,sp|P80297|MT1X_HUMAN | G15: 1876.7427 | H15: 499 | I15: 3 | J15: 1876.689 | K15: 626.5882 | L15: Metallothionein-1B OS=Homo sapiens GN=MT1B PE=2 SV=1 | M15: 8.38 | N15: 2002.46 | O15: -28.567407 | P15: 34.9 | Q15: 22.8 | R15: 6.8 | S15: 10.6 | T15: 0.0004 | U15: -0.0537 | V15: 6.2353
... A476: 0.9423 | B476: MegaP_hMMP9_Tryps_AP_QStar-XL_20080502.07357.07357.2 | C476: 7357 | D476: 9/20 | E476: R.n[29.04]LHFFM[147.04]PGFAPL.T | F476: sp|P07437|TBB5_HUMAN,sp|Q9H4B7|TBB1_HUMAN,sp|Q13885|TBB2A_HUMAN,sp|Q9BVA1|TBB2B_HUMAN,sp|Q13509|TBB3_HUMAN,sp|P04350|TBB4A_HUMAN,sp|P68371|TBB4B_HUMAN,sp|Q9BUF5|TBB6_HUMAN,sp|A6NNZ2|TBB8L_HUMAN,sp|Q3ZCM7|TBB8_HUMAN,sp|A6NKZ8|YI016_HUMAN,CON_ENSBTAP00000025008|ENSBTAP00000025008 | G476: 1319.6737 | H476: 729 | I476: 2 | J476: 1319.6472 | K476: 660.8441 | L476: Tubulin beta chain OS=Homo sapiens GN=TUBB PE=1 SV=2 | M476: 6.74 | N476: 7887.18 | O476: -20.050115 | P476: 27.2 | Q476: 20.3 | R476: 8.1 | S476: 10.8 | T476: 0.12 | U476: -0.0265 | V476: 2.6466

Sheet MMP12-T
A1: Supplementary Table 1g: Human MMP12 cleavage sites identified by PICS in trypsin-generated human proteome libraries | J1: back to index
A2: Peptides were identified by LC-MS/MS spectrum-to-sequence assignment with Mascot and X! Tandem, and further analysed by iProphet within TPP at a false-discovery rate of 1%. iProphet probability score, spectrum ID, peptide sequence, and scores by Mascot (ionscore, identity score, homology score) and X! Tandem (hyperscore, nextscore, bscore, yscore) are shown together with other peptide and peptide-spectrum match measures. One exemplary accession number of a matching UniProt protein entry is listed. K[156.13] denotes lysine labeled by heavy-dimethyl, C[160.03] and M[147.04] represent carbamidomethylated cysteine and oxidized methionine, respectively, and n[89.01] indicates thioacylated N-termini. Data were further processed and rendered non-redundant for generation of cleavage specificity profiles via WebPICS (http://clipserve.clip.ubc.ca/pics/) and iceLogo (http://iomics.ugent.be/icelogoserver/).
A3: ='MMP1-T'!A3 -> probability | B3: ='MMP1-T'!B3 -> spectrum | C3: ='MMP1-T'!C3 -> start scan | D3: ='MMP1-T'!D3 -> ions | E3: ='MMP1-T'!E3 -> peptide | F3: ='MMP1-T'!F3 -> protein | G3: ='MMP1-T'!G3 -> calculated neutral peptide mass | H3: ='MMP1-T'!H3 -> index | ... V3: ='MMP1-T'!V3 -> fval
A4: 1 | B4: MegaP_hMMP12_Tryps_CB_QStar-XL_20080812.01294.01294.3 | C4: 1294 | D4: 18/56 | E4: S.n[89.01]QK[156.13]GESAEDK[156.13]EHEEGR.D | F4: sp|Q7Z4V5|HDGR2_HUMAN,sp|Q7Z4V5-2|HDGR2_HUMAN,sp|Q7Z4V5-3|HDGR2_HUMAN | G4: 1871.8317 | H4: 528 | I4: 3 | J4: 1871.7872 | K4: 624.9512 | L4: Hepatoma-derived growth factor-related protein 2 OS=Homo sapiens GN=HDGFRP2 PE=1 SV=1 | M4: 4.7 | N4: 1358.81 | O4: -23.735187 | P4: 40.7 | Q4: 21.7 | R4: 8.8 | S4: 10.2 | T4: 1.3e-05 | U4: -0.0445 | V4: 8.4205
A5: 0.9999 | B5: MegaP_hMMP12_Tryps_CB_QStar-XL_20080812.01382.01382.3 | C5: 1382 | D5: 19/56 | E5: H.n[89.01]QQHHQGPPPGGPGGR.S | F5: sp|P23246|SFPQ_HUMAN,sp|P23246-2|SFPQ_HUMAN | G5: 1593.7217 | H5: 772 | I5: 3 | J5: 1593.6806 | K5: 532.2478 | L5: Splicing factor, proline- and glutamine-rich OS=Homo sapiens GN=SFPQ PE=1 SV=2 | M5: 9.76 | N5: 1456.47 | O5: -25.73989 | P5: 43.9 | Q5: 25.7 | R5: 11.4 | S5: 12.3 | T5: 2.9e-05 | U5: -0.0411 | V5: 7.7363
A6: 0.9991 | B6: MegaP_hMMP12_Tryps_CB_QStar-XL_20080812.01408.01408.3 | C6: 1408 | D6: 17/56 | E6: H.n[89.01]QQHHQGPPPGGPGGR.S | F6: sp|P23246|SFPQ_HUMAN,sp|P23246-2|SFPQ_HUMAN | G6: 1593.7217 | H6: 529 | I6: 3 | J6: 1593.69 | K6: 532.2478 | L6: Splicing factor, proline- and glutamine-rich OS=Homo sapiens GN=SFPQ PE=1 SV=2 | M6: 9.76 | N6: 1482.72 | O6: -19.852908 | P6: 38 | Q6: 25.7 | R6: 11.1 | S6: 11.8 | T6: 0.0016 | U6: -0.0317 | V6: 5.1959
A7: 0.9999 | B7: MegaP_hMMP12_Tryps_CB_QStar-XL_20080812.01435.01435.3 | C7: 1435 | D7: 19/56 | E7: H.n[89.01]QQHHQGPPPGGPGGR.S | F7: sp|P23246|SFPQ_HUMAN,sp|P23246-2|SFPQ_HUMAN | G7: 1593.7217 | H7: 85 | I7: 3 | J7: 1593.6971 | K7: 532.2478 | L7: Splicing factor, proline- and glutamine-rich OS=Homo sapiens GN=SFPQ PE=1 SV=2 | M7: 9.76 | N7: 1513.17 | O7: -15.406358 | P7: 43.5 | Q7: 26.4 | R7: 10.6 | S7: 11.6 | T7: 0.00027 | U7: -0.0246 | V7: 6.4733
A8: 0.9999 | B8: MegaP_hMMP12_Tryps_CB_QStar-XL_20080812.01466.01466.3 | C8: 1466 | D8: 18/56 | E8: H.n[89.01]QQHHQGPPPGGPGGR.S | F8: sp|P23246|SFPQ_HUMAN,sp|P23246-2|SFPQ_HUMAN | G8: 1593.7217 | H8: 2 | I8: 3 | J8: 1593.6936 | K8: 532.2478 | L8: Splicing factor, proline- and glutamine-rich OS=Homo sapiens GN=SFPQ PE=1 SV=2 | M8: 9.76 | N8: 1546.77 | O8: -17.598319 | P8: 41.6 | Q8: 28.4 | R8: 11 | S8: 12.7 | T8: 0.00042 | U8: -0.0281 | V8: 5.8537
A9: 0.9965 | B9: MegaP_hMMP12_Tryps_CB_QStar-XL_20080812.01495.01495.3 | C9: 1495 | D9: 15/56 | E9: H.n[89.01]QQHHQGPPPGGPGGR.S | F9: sp|P23246|SFPQ_HUMAN,sp|P23246-2|SFPQ_HUMAN | G9: 1593.7217 | H9: 459 | I9: 3 | J9: 1593.6966 | K9: 532.2478 | L9: Splicing factor, proline- and glutamine-rich OS=Homo sapiens GN=SFPQ PE=1 SV=2 | M9: 9.76 | N9: 1578.27 | O9: -15.719495 | P9: 33.3 | Q9: 24.5 | R9: 11.4 | S9: 12.5 | T9: 0.036 | U9: -0.0251 | V9: 3.2813
A10: 0.9938 | B10: MegaP_hMMP12_Tryps_CB_QStar-XL_20080812.01574.01574.2 | C10: 1574 | D10: 12/18 | E10: E.n[89.01]QQQQTPAENK[156.13].A | F10: sp|P34932|HSP74_HUMAN | G10: 1286.5927 | H10: 1123 | I10: 2 | J10: 1286.582 | K10: 644.3036 | L10: Heat shock 70 kDa protein 4 OS=Homo sapiens GN=HSPA4 PE=1 SV=4 | M10: 6 | N10: 1664.37 | O10: -8.3035389 | P10: 36.5 | Q10: 26.3 | R10: 10.2 | S10: 12 | T10: 0.026 | U10: -0.0107 | V10: 3.6605
A11: 0.9965 | B11: MegaP_hMMP12_Tryps_CB_QStar-XL_20080812.01600.01600.2 | C11: 1600 | D11: 10/20 | E11: P.n[89.01]QAK[156.13]PSNPSNPR.V | F11: sp|Q08752|PPID_HUMAN | G11: 1310.6397 | H11: 460 | I11: 2 | J11: 1310.6001 | K11: 656.3271 | L11: Peptidyl-prolyl cis-trans isomerase D OS=Homo sapiens GN=PPID PE=1 SV=3 | M11: 11 | N11: 1693.77 | O11: -30.167884 | P11: 29.8 | Q11: 22.8 | R11: 11.7 | S11: 12.2 | T11: 0.028 | U11: -0.0396 | V11: 3.2581
A12: 1 | B12: MegaP_hMMP12_Tryps_CB_QStar-XL_20080812.01629.01629.3 | C12: 1629 | D12: 16/40 | E12: P.n[89.01]C[160.03]THPEDK[156.13]PAPK[156.13].N | F12: sp|Q9H0D6|XRN2_HUMAN | G12: 1422.6637 | H12: 531 | I12: 3 | J12: 1422.6324 | K12: 475.2285 | L12: 5'-3' exoribonuclease 2 OS=Homo sapiens GN=XRN2 PE=1 SV=1 | M12: 6.74 | N12: 1727.37 | O12: -21.954351 | P12: 41.4 | Q12: 25.7 | R12: 7 | S12: 12 | T12: 5.8e-05 | U12: -0.0313 | V12: 8.3694
A13: 0.9997 | B13: MegaP_hMMP12_Tryps_CB_QStar-XL_20080812.01651.01651.2 | C13: 1651 | D13: 13/22 | E13: N.n[89.01]QQSSGAAGPTGK[156.13].N | F13: sp|O95232|LC7L3_HUMAN | G13: 1203.5557 | H13: 1125 | I13: 2 | J13: 1203.5272 | K13: 602.7851 | L13: Luc7-like protein 3 OS=Homo sapiens GN=LUC7L3 PE=1 SV=2 | M13: 8.75 | N13: 1754.67 | O13: -23.640266 | P13: 41.6 | Q13: 26.8 | R13: 10.3 | S13: 11.6 | T13: 5.1e-05 | U13: -0.0285 | V13: 6.6083
A14: 0.9713 | B14: MegaP_hMMP12_Tryps_CB_QStar-XL_20080812.01651.01651.4 | C14: 1651 | D14: 11/132 | E14: R.n[89.01]RGHARLALSQNQQSSGAAGPTGK[156.13].N | F14: sp|O95232|LC7L3_HUMAN | G14: 2407.2137 | H14: 395 | I14: 4 | J14: 2407.0544 | K14: 602.8107 | L14: Luc7-like protein 3 OS=Homo sapiens GN=LUC7L3 PE=1 SV=2 | M14: 12.01 | N14: 1754.67 | O14: -66.065516 | P14: 38 | Q14: 26.8 | R14: 8.8 | S14: 11.4 | T14: 0.0025 | U14: -0.1593 | V14: 3.9278
A15: 0.9996 | B15: MegaP_hMMP12_Tryps_CB_QStar-XL_20080812.01707.01707.2 | C15: 1707 | D15: 14/22 | E15: H.n[89.01]HQGPPPGGPGGR.S | F15: sp|P23246|SFPQ_HUMAN,sp|P23246-2|SFPQ_HUMAN | G15: 1200.5457 | H15: 916 | I15: 2 | J15: 1200.5241 | K15: 601.2801 | L15: Splicing factor, proline- and glutamine-rich OS=Homo sapiens GN=SFPQ PE=1 SV=2 | M15: 9.76 | N15: 1817.78 | O15: -17.961679 | P15: 43.1 | Q15: 26.3 | R15: 10 | S15: 10.3 | T15: 3.6e-05 | U15: -0.0216 | V15: 6.9263
... A484: 0.9974 | B484: MegaP_hMMP12_Tryps_CB_QStar-XL_20080812.06442.06442.2 | C484: 6442 | D484: 16/18 | E484: P.n[89.01]LRLPLQDVYK[156.13].L | F484: sp|P68104|EF1A1_HUMAN,sp|Q05639|EF1A2_HUMAN,sp|Q5VTE0|EF1A3_HUMAN | G484: 1359.7587 | H484: 220 | I484: 2 | J484: 1359.7367 | K484: 680.8866 | L484: Elongation factor 1-alpha 1 OS=Homo sapiens GN=EEF1A1 PE=1 SV=1 | M484: 8.59 | N484: 7009.25 | O484: -16.155407 | P484: 50.5 | Q484: 35.1 | R484: 11.7 | S484: 12.6 | T484: 0.0023 | U484: -0.022 | V484: 5.0166

Sheet MMP13-T
A1: Supplementary Table 1h: Human MMP13 cleavage sites identified by PICS in trypsin-generated human proteome libraries | J1: back to index
A2: Peptides were identified by LC-MS/MS spectrum-to-sequence assignment with Mascot and X! Tandem, and further analysed by iProphet within TPP at a false-discovery rate of 1%. iProphet probability score, spectrum ID, peptide sequence, and scores by Mascot (ionscore, identity score, homology score) and X! Tandem (hyperscore, nextscore, bscore, yscore) are shown together with other peptide and peptide-spectrum match measures. One exemplary accession number of a matching UniProt protein entry is listed. K[156.13] denotes lysine labeled by heavy-dimethyl, C[160.03] and M[147.04] represent carbamidomethylated cysteine and oxidized methionine, respectively, and n[89.01] indicates thioacylated N-termini. Data were further processed and rendered non-redundant for generation of cleavage specificity profiles via WebPICS (http://clipserve.clip.ubc.ca/pics/) and iceLogo (http://iomics.ugent.be/icelogoserver/).
A3: ='MMP1-T'!A3 -> probability | B3: ='MMP1-T'!B3 -> spectrum | C3: ='MMP1-T'!C3 -> start scan | D3: ='MMP1-T'!D3 -> ions | E3: ='MMP1-T'!E3 -> peptide | F3: ='MMP1-T'!F3 -> protein | G3: ='MMP1-T'!G3 -> calculated neutral peptide mass | H3: ='MMP1-T'!H3 -> index | ... V3: ='MMP1-T'!V3 -> fval
A4: 0.9989 | B4: MegaP_hMMP13_Tryps_UdK_QStar-XL_20080502.01573.01573.4 | C4: 1573 | D4: 20/84 | E4: P.n[89.01]QQHPQQHPQNQAHGK[156.13].G | F4: sp|Q07065|CKAP4_HUMAN | G4: 1877.8707 | H4: 618 | I4: 4 | J4: 1877.9341 | K4: 470.475 | L4: Cytoskeleton-associated protein 4 OS=Homo sapiens GN=CKAP4 PE=1 SV=2 | M4: 8.77 | N4: 1650.6 | O4: 33.689357 | P4: 36.2 | Q4: 23.5 | R4: 9.9 | S4: 12.1 | T4: 0.00064 | U4: 0.0634 | V4: 5.8093
A5: 0.943 | B5: MegaP_hMMP13_Tryps_UdK_QStar-XL_20080502.01667.01667.4 | C5: 1667 | D5: 9/90 | E5: S.n[29.04]PPQNASNNPTPANAAK[156.13].S | F5: sp|O43365|HXA3_HUMAN | G5: 1646.8377 | H5: 437 | I5: 4 | J5: 1646.9973 | K5: 412.7167 | L5: Homeobox protein Hox-A3 OS=Homo sapiens GN=HOXA3 PE=2 SV=1 | M5: 9.18 | N5: 1754.56 | O5: 96.676485 | P5: 23.6 | Q5: 19.2 | R5: 11.5 | S5: 10.2 | T5: 0.22 | U5: 0.1596 | V5: 1.8893
A6: 0.9997 | B6: MegaP_hMMP13_Tryps_UdK_QStar-XL_20080502.01697.01697.4 | C6: 1697 | D6: 21/72 | E6: K.n[29.04]YHTINGHNC[160.03]EVK[156.13]K[156.13].A | F6: sp|P51991|ROA3_HUMAN,sp|P51991-2|ROA3_HUMAN | G6: 1682.8567 | H6: 915 | I6: 4 | J6: 1682.9062 | K6: 421.7215 | L6: Heterogeneous nuclear ribonucleoprotein A3 OS=Homo sapiens GN=HNRNPA3 PE=1 SV=2 | M6: 8.19 | N6: 1806.01 | O6: 29.34401 | P6: 39.5 | Q6: 29.7 | R6: 6.6 | S6: 8.3 | T6: 0.00013 | U6: 0.0495 | V6: 6.5397
A7: 1 | B7: MegaP_hMMP13_Tryps_UdK_QStar-XL_20080502.01700.01700.3 | C7: 1700 | D7: 14/44 | E7: K.n[29.04]APGTPHSHTK[156.13]PY.V | F7: sp|Q07020|RL18_HUMAN | G7: 1347.6937 | H7: 619 | I7: 3 | J7: 1347.7104 | K7: 450.2385 | L7: 60S ribosomal protein L18 OS=Homo sapiens GN=RPL18 PE=1 SV=2 | M7: 8.65 | N7: 1807.06 | O7: 12.363818 | P7: 34.4 | Q7: 19.4 | R7: 2 | S7: 11.3 | T7: 1.2e-05 | U7: 0.0167 | V7: 9.2592
A8: 0.9998 | B8: MegaP_hMMP13_Tryps_UdK_QStar-XL_20080502.01706.01706.3 | C8: 1706 | D8: 11/44 | E8: K.n[29.04]YHTVNGHNC[160.03]EVR.K | F8: sp|P09651|ROA1_HUMAN,sp|P09651-2|ROA1_HUMAN,sp|P09651-3|ROA1_HUMAN | G8: 1512.6887 | H8: 620 | I8: 3 | J8: 1512.7159 | K8: 505.2368 | L8: Heterogeneous nuclear ribonucleoprotein A1 OS=Homo sapiens GN=HNRNPA1 PE=1 SV=5 | M8: 6.91 | N8: 1818.61 | O8: 17.945381 | P8: 28.3 | Q8: 16.5 | R8: 6.1 | S8: 8.2 | T8: 0.0051 | U8: 0.0272 | V8: 5.6549
A9: 0.9997 | B9: MegaP_hMMP13_Tryps_UdK_QStar-XL_20080502.01729.01729.3 | C9: 1729 | D9: 13/48 | E9: K.n[29.04]YHTINGHNAEVRK[156.13].A | F9: sp|P22626|ROA2_HUMAN,sp|P22626-2|ROA2_HUMAN | G9: 1593.8377 | H9: 343 | I9: 3 | J9: 1593.8528 | K9: 532.2865 | L9: Heterogeneous nuclear ribonucleoproteins A2\B1 OS=Homo sapiens GN=HNRNPA2B1 PE=1 SV=2 | M9: 8.6 | N9: 1856.41 | O9: 9.4560605 | P9: 27.5 | Q9: 16.7 | R9: 4 | S9: 6.2 | T9: 0.0018 | U9: 0.0151 | V9: 5.8841
A10: 0.9782 | B10: MegaP_hMMP13_Tryps_UdK_QStar-XL_20080502.01745.01745.4 | C10: 1745 | D10: 15/90 | E10: R.n[89.01]AALSPAGALLLQPPAR.R | F10: sp|Q96JY6-5|PDLI2_HUMAN | G10: 1632.9017 | H10: 2 | I10: 4 | J10: 1632.9394 | K10: 409.2327 | L10: Isoform 5 of PDZ and LIM domain protein 2 OS=Homo sapiens GN=PDLIM2 | M10: 9.79 | N10: 1879.51 | O10: 23.030906 | P10: 29.9 | Q10: 24.9 | R10: 11.4 | S10: 12.6 | T10: 0.1 | U10: 0.0377 | V10: 2.1874
A11: 0.9672 | B11: MegaP_hMMP13_Tryps_UdK_QStar-XL_20080502.01767.01767.3 | C11: 1767 | D11: 14/48 | E11: R.n[29.04]HSLGLRSLGLTM[147.04]R.R | F11: sp|Q9UJ96|KCNG2_HUMAN | G11: 1483.8297 | H11: 97 | I11: 3 | J11: 1483.7179 | K11: 495.6172 | L11: Potassium voltage-gated channel subfamily G member 2 OS=Homo sapiens GN=KCNG2 PE=1 SV=1 | M11: 12 | N11: 1907.86 | O11: -75.19244 | P11: 27.5 | Q11: 22.3 | R11: 8.3 | S11: 9.6 | T11: 0.049 | U11: -0.1118 | V11: 2.9218
A12: 0.9998 | B12: MegaP_hMMP13_Tryps_UdK_QStar-XL_20080502.01775.01775.4 | C12: 1775 | D12: 17/78 | E12: R.n[89.01]K[156.13]SAPATGGVK[156.13]K[156.13]PHR.Y | F12: sp|Q16695|H31T_HUMAN,sp|P68431|H31_HUMAN,sp|Q71DI3|H32_HUMAN | G12: 1604.9187 | H12: 622 | I12: 4 | J12: 1604.9661 | K12: 402.237 | L12: Histone H3.1t OS=Homo sapiens GN=HIST3H3 PE=1 SV=3 | M12: 11.26 | N12: 1921.51 | O12: 29.460244 | P12: 35.8 | Q12: 23.1 | R12: 11.1 | S12: 9.7 | T12: 0.00035 | U12: 0.0474 | V12: 6.3497
A13: 0.999 | B13: MegaP_hMMP13_Tryps_UdK_QStar-XL_20080502.01777.01777.3 | C13: 1777 | D13: 17/56 | E13: H.n[89.01]QQHHQGPPPGGPGGR.S | F13: sp|P23246|SFPQ_HUMAN,sp|P23246-2|SFPQ_HUMAN | G13: 1593.7217 | H13: 441 | I13: 3 | J13: 1593.7788 | K13: 532.2478 | L13: Splicing factor, proline- and glutamine-rich OS=Homo sapiens GN=SFPQ PE=1 SV=2 | M13: 9.76 | N13: 1924.66 | O13: 35.760286 | P13: 37.9 | Q13: 25.6 | R13: 10.5 | S13: 12 | T13: 0.0012 | U13: 0.0571 | V13: 5.3489
A14: 0.9829 | B14: MegaP_hMMP13_Tryps_UdK_QStar-XL_20080502.01790.01790.2 | C14: 1790 | D14: 8/14 | E14: P.n[89.01]NGMDADC[160.03]K[156.13].D | F14: sp|Q8TB72|PUM2_HUMAN,sp|Q8TB72-2|PUM2_HUMAN,sp|Q8TB72-3|PUM2_HUMAN | G14: 1025.3617 | H14: 294 | I14: 2 | J14: 1025.1671 | K14: 513.6881 | L14: Pumilio homolog 2 OS=Homo sapiens GN=PUM2 PE=1 SV=2 | M14: 4.21 | N14: 1945.66 | O14: -189.41455 | P14: 28.1 | Q14: 19.9 | R14: 0 | S14: 9.7 | T14: 0.002 | U14: -0.1946 | V14: 5.5663
A15: 0.9998 | B15: MegaP_hMMP13_Tryps_UdK_QStar-XL_20080502.01798.01798.3 | C15: 1798 | D15: 18/56 | E15: H.n[89.01]QQHHQGPPPGGPGGR.S | F15: sp|P23246|SFPQ_HUMAN,sp|P23246-2|SFPQ_HUMAN | G15: 1593.7217 | H15: 443 | I15: 3 | J15: 1593.753 | K15: 532.2478 | L15: Splicing factor, proline- and glutamine-rich OS=Homo sapiens GN=SFPQ PE=1 SV=2 | M15: 9.76 | N15: 1955.11 | O15: 19.602398 | P15: 41 | Q15: 23 | R15: 10.5 | S15: 11.9 | T15: 0.00028 | U15: 0.0313 | V15: 6.6916
... A433: 0.9667 | B433: MegaP_hMMP13_Tryps_UdK_QStar-XL_20080502.07240.07240.2 | C433: 7240 | D433: 10/20 | E433: R.n[29.04]LHFFM[147.04]PGFAPL.T | F433: sp|P07437|TBB5_HUMAN,sp|Q9H4B7|TBB1_HUMAN,sp|Q13885|TBB2A_HUMAN,sp|Q9BVA1|TBB2B_HUMAN,sp|Q13509|TBB3_HUMAN,sp|P04350|TBB4A_HUMAN,sp|P68371|TBB4B_HUMAN,sp|Q9BUF5|TBB6_HUMAN,sp|A6NNZ2|TBB8L_HUMAN,sp|Q3ZCM7|TBB8_HUMAN,sp|A6NKZ8|YI016_HUMAN,CON_ENSBTAP00000025008|ENSBTAP00000025008 | G433: 1319.6737 | H433: 276 | I433: 2 | J433: 1319.6944 | K433: 660.8441 | L433: Tubulin beta chain OS=Homo sapiens GN=TUBB PE=1 SV=2 | M433: 6.74 | N433: 7875.08 | O433: 15.661788 | P433: 29.3 | Q433: 19.6 | R433: 8.9 | S433: 10.9 | T433: 0.027 | U433: 0.0207 | V433: 3.7395

Sheet MMP14-T
A1: Supplementary Table 1i: Human MMP14 cleavage sites identified by PICS in trypsin-generated human proteome libraries | J1: back to index
